Workbook
Name STATUS_PROCESSO: #REF!
Name STATUSINFRA: '[2]Apoio IE'!$F$2:$F$16

Sheet PARÂMETROS
A1: BASE CONSOLIDADA LPU LS — PARÂMETROS
A3: Parâmetro | B3: Valor | C3: O que significa
A4: Fator sobre o MERCADO | B4: 0.9 | C4: LS OFFICE = MERCADO da região × este fator. 0,90 = entrar 10% abaixo da mediana dos fornecedores. Altere e as colunas LS OFFICE recalculam, aqui e na aba LPU ADEQUAÇÃO.
A5: Fator sobre o CUSTO | B5: 3.34 | C5: PREÇO POR CUSTO = CUSTO LS × este fator. O valor sugerido é a mediana do que a LS já praticou sobre o próprio custo nas linhas onde as duas pontas existem — não é uma meta, é o retrato do que vem sendo cobrado. Calibre.
A6: MERCADO — critério | B6: Mediana | C6: Mediana das cotações de fornecedor válidas da região, ignorando n/a, N/A e zeros. Mediana e não média: em vários itens a Clemar cota 5x a Brasilsat, e a média sozinha seria puxada pelo extremo.
A7: MERCADO NORTE / NORDESTE | B7: Por região | C7: Cada uma usa só os fornecedores daquele bloco da LPU: 7 no Norte, 8 no Nordeste.
A8: MERCADO N+NE | B8: Duas regiões juntas | C8: Mediana das cotações do Norte e do Nordeste somadas — as regiões onde a LS opera. É esta, não a do Brasil, que serve de referência geral.
A9: MERCADO BRASIL | B9: As 6 regiões | C9: Mediana de todas as cotações das 6 regiões. Fica na base só como referência: Leste e Sul são muito mais caros e distorcem o número para cima.
A10: CUSTO LS | B10: Média | C10: Média do valor unitário efetivamente pago, apenas documentos marcados SIM na planilha de itens comprados. É material posto na obra: sem mão de obra, sem BDI.
A11: PRATICADO | B11: Média | C11: Média das PVs que precificaram o item — 36 PVs, uma por site, revisão mais recente.
A12: Rastreabilidade | B12: — | C12: Cada cotação de fornecedor que entra em qualquer mediana está na aba ABERTURA DE MERCADO, linha por linha, com região e nome do fornecedor.

Sheet BASE CONSOLIDADA
A1: Linha LPU | B1: Família | C1: Grupo | D1: Subgrupo | E1: Item | F1: Un. | G1: Simples | H1: Macro | I1: Altura (m) | J1: AeV (m²) | K1: Vento (m/s) | L1: Nº forn. Norte | M1: MERCADO NORTE (mediana) | N1: LS OFFICE NORTE | O1: Nº forn. Nordeste | P1: MERCADO NORDESTE (mediana) | Q1: LS OFFICE NORDESTE | R1: Nº cot. N+NE | S1: MERCADO N+NE (mediana) | T1: CUSTO LS (compras) | U1: Nº compras | V1: PREÇO POR CUSTO | W1: PRATICADO (PV média) | X1: Nº PVs | Y1: Praticado ÷ Custo | Z1: LS Office ÷ Custo | AA1: LS Office ÷ Praticado | AB1: Dispersão forn. Norte (maior÷menor) | AC1: MÉDIA original da LPU (sua fórmula) | AD1: MERCADO BRASIL (6 regiões) | AE1: Origem do de-para | AF1: Descrição completa (original da LPU)
A2: 5 | B2: MASTRO | C2: Mastro | E2: Mastro · 2m · AeV 2m² · 45m/s | F2: VB | G2: - | H2: 2 | I2: 2 | J2: 2 | K2: 45 | L2: 4 | M2: 3801.96 | N2: =IF(M2="","",ROUND(M2*PARÂMETROS!$B$4,2)) | O2: 4 | P2: 3721.96 | Q2: =IF(P2="","",ROUND(P2*PARÂMETROS!$B$4,2)) | R2: 8 | S2: 3763.92 | V2: =IF(T2="","",ROUND(T2*PARÂMETROS!$B$5,2)) | Y2: =IFERROR(ROUND(W2/T2,2),"") | Z2: =IFERROR(ROUND(N2/T2,2),"") | AA2: =IFERROR(ROUND(N2/W2,2),"") | AB2: 6.3 | AC2: 3820.06 | AD2: 3721.98 | AF2: Mastros Mastros com altura superior 2m deverão ser providos de pedaleira e cabo trava-quedas. >> 2
A3: 6 | B3: MASTRO | C3: Mastro | E3: Mastro · 3m · AeV 2m² · 45m/s | F3: VB | G3: - | H3: 2 | I3: 3 | J3: 2 | K3: 45 | L3: 4 | M3: 6071.32 | N3: =IF(M3="","",ROUND(M3*PARÂMETROS!$B$4,2)) | O3: 4 | P3: 5908.12 | Q3: =IF(P3="","",ROUND(P3*PARÂMETROS!$B$4,2)) | R3: 8 | S3: 5908.12 | V3: =IF(T3="","",ROUND(T3*PARÂMETROS!$B$5,2)) | Y3: =IFERROR(ROUND(W3/T3,2),"") | Z3: =IFERROR(ROUND(N3/T3,2),"") | AA3: =IFERROR(ROUND(N3/W3,2),"") | AB3: 5.4 | AC3: 6958.3 | AD3: 5418.52 | AF3: Mastros Mastros com altura superior 2m deverão ser providos de pedaleira e cabo trava-quedas. >> 2
A4: 7 | B4: MASTRO | C4: Mastro | E4: Mastro · 3m · AeV 3m² · 45m/s | F4: VB | G4: - | H4: 3 | I4: 3 | J4: 3 | K4: 45 | L4: 4 | M4: 6378.52 | N4: =IF(M4="","",ROUND(M4*PARÂMETROS!$B$4,2)) | O4: 4 | P4: 6202.52 | Q4: =IF(P4="","",ROUND(P4*PARÂMETROS!$B$4,2)) | R4: 8 | S4: 6202.52 | V4: =IF(T4="","",ROUND(T4*PARÂMETROS!$B$5,2)) | Y4: =IFERROR(ROUND(W4/T4,2),"") | Z4: =IFERROR(ROUND(N4/T4,2),"") | AA4: =IFERROR(ROUND(N4/W4,2),"") | AB4: 5.7 | AC4: 7277.47 | AD4: 5674.52 | AF4: Mastros Mastros com altura superior 2m deverão ser providos de pedaleira e cabo trava-quedas. >> 3
A5: 8 | B5: MASTRO | C5: Mastro | E5: Mastro · 4m · AeV 2m² · 45m/s | F5: VB | G5: - | H5: 2 | I5: 4 | J5: 2 | K5: 45 | L5: 4 | M5: 7911.45 | N5: =IF(M5="","",ROUND(M5*PARÂMETROS!$B$4,2)) | O5: 4 | P5: 7711.45 | Q5: =IF(P5="","",ROUND(P5*PARÂMETROS!$B$4,2)) | R5: 8 | S5: 7711.45 | V5: =IF(T5="","",ROUND(T5*PARÂMETROS!$B$5,2)) | Y5: =IFERROR(ROUND(W5/T5,2),"") | Z5: =IFERROR(ROUND(N5/T5,2),"") | AA5: =IFERROR(ROUND(N5/W5,2),"") | AB5: 3.5 | AC5: 8814.38 | AD5: 7111.45 | AF5: Mastros Mastros com altura superior 2m deverão ser providos de pedaleira e cabo trava-quedas. >> 2
A6: 9 | B6: MASTRO | C6: Mastro | E6: Mastro · 4m · AeV 3m² · 45m/s | F6: VB | G6: - | H6: 3 | I6: 4 | J6: 3 | K6: 45 | L6: 4 | M6: 9677.85 | N6: =IF(M6="","",ROUND(M6*PARÂMETROS!$B$4,2)) | O6: 4 | P6: 9404.25 | Q6: =IF(P6="","",ROUND(P6*PARÂMETROS!$B$4,2)) | R6: 8 | S6: 9404.25 | V6: =IF(T6="","",ROUND(T6*PARÂMETROS!$B$5,2)) | Y6: =IFERROR(ROUND(W6/T6,2),"") | Z6: =IFERROR(ROUND(N6/T6,2),"") | AA6: =IFERROR(ROUND(N6/W6,2),"") | AB6: 3.7 | AC6: 9886.65 | AD6: 8583.45 | AF6: Mastros Mastros com altura superior 2m deverão ser providos de pedaleira e cabo trava-quedas. >> 3
A7: 10 | B7: MASTRO | C7: Mastro | E7: Mastro · 6m · AeV 2m² · 45m/s | F7: VB | G7: - | H7: 2 | I7: 6 | J7: 2 | K7: 45 | L7: 4 | M7: 12883.71 | N7: =IF(M7="","",ROUND(M7*PARÂMETROS!$B$4,2)) | O7: 4 | P7: 13005.3 | Q7: =IF(P7="","",ROUND(P7*PARÂMETROS!$B$4,2)) | R7: 8 | S7: 12883.71 | V7: =IF(T7="","",ROUND(T7*PARÂMETROS!$B$5,2)) | Y7: =IFERROR(ROUND(W7/T7,2),"") | Z7: =IFERROR(ROUND(N7/T7,2),"") | AA7: =IFERROR(ROUND(N7/W7,2),"") | AB7: 3.8 | AC7: 12802.44 | AD7: 11925.19 | AF7: Mastros Mastros com altura superior 2m deverão ser providos de pedaleira e cabo trava-quedas. >> 2
A8: 11 | B8: MASTRO | C8: Mastro | E8: Mastro · 6m · AeV 3m² · 45m/s | F8: VB | G8: - | H8: 3 | I8: 6 | J8: 3 | K8: 45 | L8: 4 | M8: 15038.54 | N8: =IF(M8="","",ROUND(M8*PARÂMETROS!$B$4,2)) | O8: 4 | P8: 14096.81 | Q8: =IF(P8="","",ROUND(P8*PARÂMETROS!$B$4,2)) | R8: 8 | S8: 14096.81 | V8: =IF(T8="","",ROUND(T8*PARÂMETROS!$B$5,2)) | Y8: =IFERROR(ROUND(W8/T8,2),"") | Z8: =IFERROR(ROUND(N8/T8,2),"") | AA8: =IFERROR(ROUND(N8/W8,2),"") | AB8: 4 | AC8: 14131.97 | AD8: 13249.68 | AF8: Mastros Mastros com altura superior 2m deverão ser providos de pedaleira e cabo trava-quedas. >> 3
A9: 12 | B9: MASTRO | C9: Mastro | E9: Mastro · 8m · AeV 3m² · 45m/s | F9: VB | G9: - | H9: 3 | I9: 8 | J9: 3 | K9: 45 | L9: 4 | M9: 24845.17 | N9: =IF(M9="","",ROUND(M9*PARÂMETROS!$B$4,2)) | O9: 4 | P9: 22800.52 | Q9: =IF(P9="","",ROUND(P9*PARÂMETROS!$B$4,2)) | R9: 8 | S9: 22800.52 | V9: =IF(T9="","",ROUND(T9*PARÂMETROS!$B$5,2)) | Y9: =IFERROR(ROUND(W9/T9,2),"") | Z9: =IFERROR(ROUND(N9/T9,2),"") | AA9: =IFERROR(ROUND(N9/W9,2),"") | AB9: 5.6 | AC9: 22685.59 | AD9: 21437.41 | AF9: Mastros Mastros com altura superior 2m deverão ser providos de pedaleira e cabo trava-quedas. >> 3
A10: 13 | B10: MASTRO | C10: Mastro | E10: Mastro · 8m · AeV 4m² · 45m/s | F10: VB | G10: - | H10: 4 | I10: 8 | J10: 4 | K10: 45 | L10: 4 | M10: 25630.36 | N10: =IF(M10="","",ROUND(M10*PARÂMETROS!$B$4,2)) | O10: 4 | P10: 23550.22 | Q10: =IF(P10="","",ROUND(P10*PARÂMETROS!$B$4,2)) | R10: 8 | S10: 23550.22 | V10: =IF(T10="","",ROUND(T10*PARÂMETROS!$B$5,2)) | Y10: =IFERROR(ROUND(W10/T10,2),"") | Z10: =IFERROR(ROUND(N10/T10,2),"") | AA10: =IFERROR(ROUND(N10/W10,2),"") | AB10: 5.7 | AC10: 23319.46 | AD10: 22118.97 | AF10: Mastros Mastros com altura superior 2m deverão ser providos de pedaleira e cabo trava-quedas. >> 4
A11: 14 | B11: POSTE | C11: Poste Concreto/Fibra Simplificado | D11: Suporte RF em plataforma EV > 30m | E11: 3 | F11: VB | I11: 9 | J11: 3 | K11: 30 | L11: 1 | M11: 3375 | N11: =IF(M11="","",ROUND(M11*PARÂMETROS!$B$4,2)) | O11: 1 | P11: 3375 | Q11: =IF(P11="","",ROUND(P11*PARÂMETROS!$B$4,2)) | R11: 2 | S11: 3375 | V11: =IF(T11="","",ROUND(T11*PARÂMETROS!$B$5,2)) | Y11: =IFERROR(ROUND(W11/T11,2),"") | Z11: =IFERROR(ROUND(N11/T11,2),"") | AA11: =IFERROR(ROUND(N11/W11,2),"") | AB11: 1 | AC11: 3375 | AD11: 3375 | AF11: Poste de Concreto ou Fibra Simplificado Deflexão máxima 1◦0"00" >> Suporte RF em plataforma EV > 30m >> 3
A12: 15 | B12: POSTE | C12: Poste Concreto/Fibra Simplificado | D12: Suporte RF em plataforma EV > 30m | E12: 3 | F12: VB | I12: 9 | J12: 3 | K12: 35 | L12: 1 | M12: 3543.75 | N12: =IF(M12="","",ROUND(M12*PARÂMETROS!$B$4,2)) | O12: 1 | P12: 3543.75 | Q12: =IF(P12="","",ROUND(P12*PARÂMETROS!$B$4,2)) | R12: 2 | S12: 3543.75 | V12: =IF(T12="","",ROUND(T12*PARÂMETROS!$B$5,2)) | Y12: =IFERROR(ROUND(W12/T12,2),"") | Z12: =IFERROR(ROUND(N12/T12,2),"") | AA12: =IFERROR(ROUND(N12/W12,2),"") | AB12: 1 | AC12: 3543.75 | AD12: 3543.75 | AF12: Poste de Concreto ou Fibra Simplificado Deflexão máxima 1◦0"00" >> Suporte RF em plataforma EV > 30m >> 3
A13: 16 | B13: POSTE | C13: Poste Concreto/Fibra Simplificado | D13: Suporte TX em plataforma EV > 30m | E13: 3 | F13: VB | I13: 9 | J13: 3 | K13: 40 | L13: 1 | M13: 3720.94 | N13: =IF(M13="","",ROUND(M13*PARÂMETROS!$B$4,2)) | O13: 1 | P13: 3720.94 | Q13: =IF(P13="","",ROUND(P13*PARÂMETROS!$B$4,2)) | R13: 2 | S13: 3720.94 | V13: =IF(T13="","",ROUND(T13*PARÂMETROS!$B$5,2)) | Y13: =IFERROR(ROUND(W13/T13,2),"") | Z13: =IFERROR(ROUND(N13/T13,2),"") | AA13: =IFERROR(ROUND(N13/W13,2),"") | AB13: 1 | AC13: 3720.94 | AD13: 3720.94 | AF13: Poste de Concreto ou Fibra Simplificado Deflexão máxima 1◦0"00" >> Suporte TX em plataforma EV > 30m >> 3
A14: 17 | B14: POSTE | C14: Poste Concreto/Fibra Simplificado | D14: SPDA | E14: 3 | F14: VB | I14: 9 | J14: 3 | K14: 45 | L14: 1 | M14: 3906.98 | N14: =IF(M14="","",ROUND(M14*PARÂMETROS!$B$4,2)) | O14: 1 | P14: 3906.98 | Q14: =IF(P14="","",ROUND(P14*PARÂMETROS!$B$4,2)) | R14: 2 | S14: 3906.98 | V14: =IF(T14="","",ROUND(T14*PARÂMETROS!$B$5,2)) | Y14: =IFERROR(ROUND(W14/T14,2),"") | Z14: =IFERROR(ROUND(N14/T14,2),"") | AA14: =IFERROR(ROUND(N14/W14,2),"") | AB14: 1 | AC14: 3906.98 | AD14: 3906.98 | AF14: Poste de Concreto ou Fibra Simplificado Deflexão máxima 1◦0"00" >> SPDA >> 3
A15: 18 | B15: POSTE | C15: Poste Concreto/Fibra Simplificado | E15: Poste Concreto/Fibra Simplificado · 9m · AeV 4m² · 30m/s | F15: VB | H15: 4 | I15: 9 | J15: 4 | K15: 30 | L15: 1 | M15: 3881.25 | N15: =IF(M15="","",ROUND(M15*PARÂMETROS!$B$4,2)) | O15: 1 | P15: 3881.25 | Q15: =IF(P15="","",ROUND(P15*PARÂMETROS!$B$4,2)) | R15: 2 | S15: 3881.25 | V15: =IF(T15="","",ROUND(T15*PARÂMETROS!$B$5,2)) | Y15: =IFERROR(ROUND(W15/T15,2),"") | Z15: =IFERROR(ROUND(N15/T15,2),"") | AA15: =IFERROR(ROUND(N15/W15,2),"") | AB15: 1 | AC15: 3881.25 | AD15: 3881.25 | AF15: Poste de Concreto ou Fibra Simplificado Deflexão máxima 1◦0"00" >> 4
A16: 19 | B16: POSTE | C16: Poste Concreto/Fibra Simplificado | D16: Escada EV > 30m | E16: 4 | F16: VB | I16: 9 | J16: 4 | K16: 35 | L16: 1 | M16: 4075.31 | N16: =IF(M16="","",ROUND(M16*PARÂMETROS!$B$4,2)) | O16: 1 | P16: 4075.31 | Q16: =IF(P16="","",ROUND(P16*PARÂMETROS!$B$4,2)) | R16: 2 | S16: 4075.31 | V16: =IF(T16="","",ROUND(T16*PARÂMETROS!$B$5,2)) | Y16: =IFERROR(ROUND(W16/T16,2),"") | Z16: =IFERROR(ROUND(N16/T16,2),"") | AA16: =IFERROR(ROUND(N16/W16,2),"") | AB16: 1 | AC16: 4075.31 | AD16: 4075.31 | AF16: Poste de Concreto ou Fibra Simplificado Deflexão máxima 1◦0"00" >> Escada EV > 30m >> 4
A17: 20 | B17: POSTE | C17: Poste Concreto/Fibra Simplificado | D17: Trava quedas | E17: 4 | F17: VB | I17: 9 | J17: 4 | K17: 40 | L17: 1 | M17: 4279.08 | N17: =IF(M17="","",ROUND(M17*PARÂMETROS!$B$4,2)) | O17: 1 | P17: 4279.08 | Q17: =IF(P17="","",ROUND(P17*PARÂMETROS!$B$4,2)) | R17: 2 | S17: 4279.08 | V17: =IF(T17="","",ROUND(T17*PARÂMETROS!$B$5,2)) | Y17: =IFERROR(ROUND(W17/T17,2),"") | Z17: =IFERROR(ROUND(N17/T17,2),"") | AA17: =IFERROR(ROUND(N17/W17,2),"") | AB17: 1 | AC17: 4279.08 | AD17: 4279.08 | AF17: Poste de Concreto ou Fibra Simplificado Deflexão máxima 1◦0"00" >> Trava quedas >> 4
A18: 21 | B18: POSTE | C18: Poste Concreto/Fibra Simplificado | D18: Trava quedas | E18: 4 | F18: VB | I18: 9 | J18: 4 | K18: 45 | L18: 1 | M18: 4493.03 | N18: =IF(M18="","",ROUND(M18*PARÂMETROS!$B$4,2)) | O18: 1 | P18: 4493.03 | Q18: =IF(P18="","",ROUND(P18*PARÂMETROS!$B$4,2)) | R18: 2 | S18: 4493.03 | V18: =IF(T18="","",ROUND(T18*PARÂMETROS!$B$5,2)) | Y18: =IFERROR(ROUND(W18/T18,2),"") | Z18: =IFERROR(ROUND(N18/T18,2),"") | AA18: =IFERROR(ROUND(N18/W18,2),"") | AB18: 1 | AC18: 4493.03 | AD18: 4493.03 | AF18: Poste de Concreto ou Fibra Simplificado Deflexão máxima 1◦0"00" >> Trava quedas >> 4
A19: 22 | B19: POSTE | C19: Poste Concreto/Fibra Simplificado | D19: Esteriamento Horizontal EV > 30m | E19: 5 | F19: VB | I19: 9 | J19: 5 | K19: 30 | L19: 1 | M19: 4463.44 | N19: =IF(M19="","",ROUND(M19*PARÂMETROS!$B$4,2)) | O19: 1 | P19: 4463.44 | Q19: =IF(P19="","",ROUND(P19*PARÂMETROS!$B$4,2)) | R19: 2 | S19: 4463.44 | V19: =IF(T19="","",ROUND(T19*PARÂMETROS!$B$5,2)) | Y19: =IFERROR(ROUND(W19/T19,2),"") | Z19: =IFERROR(ROUND(N19/T19,2),"") | AA19: =IFERROR(ROUND(N19/W19,2),"") | AB19: 1 | AC19: 4463.44 | AD19: 4463.44 | AF19: Poste de Concreto ou Fibra Simplificado Deflexão máxima 1◦0"00" >> Esteriamento Horizontal EV > 30m >> 5
A20: 23 | B20: POSTE | C20: Poste Concreto/Fibra Simplificado | D20: Esteriamento Horizontal EV > 30m | E20: 5 | F20: VB | I20: 9 | J20: 5 | K20: 35 | L20: 1 | M20: 4686.61 | N20: =IF(M20="","",ROUND(M20*PARÂMETROS!$B$4,2)) | O20: 1 | P20: 4686.61 | Q20: =IF(P20="","",ROUND(P20*PARÂMETROS!$B$4,2)) | R20: 2 | S20: 4686.61 | V20: =IF(T20="","",ROUND(T20*PARÂMETROS!$B$5,2)) | Y20: =IFERROR(ROUND(W20/T20,2),"") | Z20: =IFERROR(ROUND(N20/T20,2),"") | AA20: =IFERROR(ROUND(N20/W20,2),"") | AB20: 1 | AC20: 4686.61 | AD20: 4686.61 | AF20: Poste de Concreto ou Fibra Simplificado Deflexão máxima 1◦0"00" >> Esteriamento Horizontal EV > 30m >> 5
A21: 24 | B21: POSTE | C21: Poste Concreto/Fibra Simplificado | D21: Esteriamento Horizontal EV > 30m | E21: 5 | F21: VB | I21: 9 | J21: 5 | K21: 40 | L21: 1 | M21: 4920.94 | N21: =IF(M21="","",ROUND(M21*PARÂMETROS!$B$4,2)) | O21: 1 | P21: 4920.94 | Q21: =IF(P21="","",ROUND(P21*PARÂMETROS!$B$4,2)) | R21: 2 | S21: 4920.94 | V21: =IF(T21="","",ROUND(T21*PARÂMETROS!$B$5,2)) | Y21: =IFERROR(ROUND(W21/T21,2),"") | Z21: =IFERROR(ROUND(N21/T21,2),"") | AA21: =IFERROR(ROUND(N21/W21,2),"") | AB21: 1 | AC21: 4920.94 | AD21: 4920.94 | AF21: Poste de Concreto ou Fibra Simplificado Deflexão máxima 1◦0"00" >> Esteriamento Horizontal EV > 30m >> 5
A22: 25 | B22: POSTE | C22: Poste Concreto/Fibra Simplificado | D22: Balizamento Baixa Intensidade EV até 45m | E22: 5 | F22: VB | I22: 9 | J22: 5 | K22: 45 | L22: 1 | M22: 5166.99 | N22: =IF(M22="","",ROUND(M22*PARÂMETROS!$B$4,2)) | O22: 1 | P22: 5166.99 | Q22: =IF(P22="","",ROUND(P22*PARÂMETROS!$B$4,2)) | R22: 2 | S22: 5166.99 | V22: =IF(T22="","",ROUND(T22*PARÂMETROS!$B$5,2)) | Y22: =IFERROR(ROUND(W22/T22,2),"") | Z22: =IFERROR(ROUND(N22/T22,2),"") | AA22: =IFERROR(ROUND(N22/W22,2),"") | AB22: 1 | AC22: 5166.99 | AD22: 5166.99 | AF22: Poste de Concreto ou Fibra Simplificado Deflexão máxima 1◦0"00" >> Balizamento Baixa Intensidade EV até 45m >> 5
A23: 26 | B23: POSTE | C23: Poste Metálico Simplificado | E23: Poste Metálico Simplificado · 9m · AeV 3m² · 30m/s | F23: VB | H23: 3 | I23: 9 | J23: 3 | K23: 30 | L23: 5 | M23: 8018.55 | N23: =IF(M23="","",ROUND(M23*PARÂMETROS!$B$4,2)) | O23: 5 | P23: 8018.55 | Q23: =IF(P23="","",ROUND(P23*PARÂMETROS!$B$4,2)) | R23: 10 | S23: 8018.55 | V23: =IF(T23="","",ROUND(T23*PARÂMETROS!$B$5,2)) | Y23: =IFERROR(ROUND(W23/T23,2),"") | Z23: =IFERROR(ROUND(N23/T23,2),"") | AA23: =IFERROR(ROUND(N23/W23,2),"") | AB23: 4.7 | AC23: 12075.67 | AD23: 8018.55 | AF23: Poste de Metálico Simplificado Deflexão máxima 1◦0"00" Fornecimento de Poste inclui gabaritos, peças, placa de identificação, parafusos e tudo o que for necessário para sua correta instalação, sempre galvanizado a quente (≥ 84micron, NBR 6323). >> 3
A24: 27 | B24: POSTE | C24: Poste Metálico Simplificado | E24: Poste Metálico Simplificado · 9m · AeV 3m² · 35m/s | F24: VB | H24: 3 | I24: 9 | J24: 3 | K24: 35 | L24: 5 | M24: 8018.55 | N24: =IF(M24="","",ROUND(M24*PARÂMETROS!$B$4,2)) | O24: 5 | P24: 8018.55 | Q24: =IF(P24="","",ROUND(P24*PARÂMETROS!$B$4,2)) | R24: 10 | S24: 8018.55 | V24: =IF(T24="","",ROUND(T24*PARÂMETROS!$B$5,2)) | Y24: =IFERROR(ROUND(W24/T24,2),"") | Z24: =IFERROR(ROUND(N24/T24,2),"") | AA24: =IFERROR(ROUND(N24/W24,2),"") | AB24: 4.7 | AC24: 12101.49 | AD24: 8018.55 | AF24: Poste de Metálico Simplificado Deflexão máxima 1◦0"00" Fornecimento de Poste inclui gabaritos, peças, placa de identificação, parafusos e tudo o que for necessário para sua correta instalação, sempre galvanizado a quente (≥ 84micron, NBR 6323). >> 3
A25: 28 | B25: POSTE | C25: Poste Metálico Simplificado | E25: Poste Metálico Simplificado · 9m · AeV 3m² · 40m/s | F25: VB | H25: 3 | I25: 9 | J25: 3 | K25: 40 | L25: 5 | M25: 8744.2 | N25: =IF(M25="","",ROUND(M25*PARÂMETROS!$B$4,2)) | O25: 5 | P25: 8744.2 | Q25: =IF(P25="","",ROUND(P25*PARÂMETROS!$B$4,2)) | R25: 10 | S25: 8744.2 | V25: =IF(T25="","",ROUND(T25*PARÂMETROS!$B$5,2)) | Y25: =IFERROR(ROUND(W25/T25,2),"") | Z25: =IFERROR(ROUND(N25/T25,2),"") | AA25: =IFERROR(ROUND(N25/W25,2),"") | AB25: 3.2 | AC25: 12723.31 | AD25: 8744.2 | AF25: Poste de Metálico Simplificado Deflexão máxima 1◦0"00" Fornecimento de Poste inclui gabaritos, peças, placa de identificação, parafusos e tudo o que for necessário para sua correta instalação, sempre galvanizado a quente (≥ 84micron, NBR 6323). >> 3
A26: 29 | B26: POSTE | C26: Poste Metálico Simplificado | E26: Poste Metálico Simplificado · 9m · AeV 3m² · 45m/s | F26: VB | H26: 3 | I26: 9 | J26: 3 | K26: 45 | L26: 5 | M26: 9469.87 | N26: =IF(M26="","",ROUND(M26*PARÂMETROS!$B$4,2)) | O26: 5 | P26: 9469.87 | Q26: =IF(P26="","",ROUND(P26*PARÂMETROS!$B$4,2)) | R26: 10 | S26: 9469.87 | V26: =IF(T26="","",ROUND(T26*PARÂMETROS!$B$5,2)) | Y26: =IFERROR(ROUND(W26/T26,2),"") | Z26: =IFERROR(ROUND(N26/T26,2),"") | AA26: =IFERROR(ROUND(N26/W26,2),"") | AB26: 3.1 | AC26: 12957.27 | AD26: 9469.87 | AF26: Poste de Metálico Simplificado Deflexão máxima 1◦0"00" Fornecimento de Poste inclui gabaritos, peças, placa de identificação, parafusos e tudo o que for necessário para sua correta instalação, sempre galvanizado a quente (≥ 84micron, NBR 6323). >> 3
A27: 30 | B27: POSTE | C27: Poste Metálico Simplificado | E27: Poste Metálico Simplificado · 9m · AeV 4m² · 30m/s | F27: VB | H27: 4 | I27: 9 | J27: 4 | K27: 30 | L27: 5 | M27: 8152.19 | N27: =IF(M27="","",ROUND(M27*PARÂMETROS!$B$4,2)) | O27: 5 | P27: 8152.19 | Q27: =IF(P27="","",ROUND(P27*PARÂMETROS!$B$4,2)) | R27: 10 | S27: 8152.19 | V27: =IF(T27="","",ROUND(T27*PARÂMETROS!$B$5,2)) | Y27: =IFERROR(ROUND(W27/T27,2),"") | Z27: =IFERROR(ROUND(N27/T27,2),"") | AA27: =IFERROR(ROUND(N27/W27,2),"") | AB27: 4.7 | AC27: 12503.95 | AD27: 8152.19 | AF27: Poste de Metálico Simplificado Deflexão máxima 1◦0"00" Fornecimento de Poste inclui gabaritos, peças, placa de identificação, parafusos e tudo o que for necessário para sua correta instalação, sempre galvanizado a quente (≥ 84micron, NBR 6323). >> 4
A28: 31 | B28: POSTE | C28: Poste Metálico Simplificado | E28: Poste Metálico Simplificado · 9m · AeV 4m² · 35m/s | F28: VB | H28: 4 | I28: 9 | J28: 4 | K28: 35 | L28: 5 | M28: 8559.8 | N28: =IF(M28="","",ROUND(M28*PARÂMETROS!$B$4,2)) | O28: 5 | P28: 8559.8 | Q28: =IF(P28="","",ROUND(P28*PARÂMETROS!$B$4,2)) | R28: 10 | S28: 8559.8 | V28: =IF(T28="","",ROUND(T28*PARÂMETROS!$B$5,2)) | Y28: =IFERROR(ROUND(W28/T28,2),"") | Z28: =IFERROR(ROUND(N28/T28,2),"") | AA28: =IFERROR(ROUND(N28/W28,2),"") | AB28: 4.7 | AC28: 12601.29 | AD28: 8559.8 | AF28: Poste de Metálico Simplificado Deflexão máxima 1◦0"00" Fornecimento de Poste inclui gabaritos, peças, placa de identificação, parafusos e tudo o que for necessário para sua correta instalação, sempre galvanizado a quente (≥ 84micron, NBR 6323). >> 4
A29: 32 | B29: POSTE | C29: Poste Metálico Simplificado | E29: Poste Metálico Simplificado · 9m · AeV 4m² · 40m/s | F29: VB | H29: 4 | I29: 9 | J29: 4 | K29: 40 | L29: 5 | M29: 8889.93 | N29: =IF(M29="","",ROUND(M29*PARÂMETROS!$B$4,2)) | O29: 5 | P29: 8889.93 | Q29: =IF(P29="","",ROUND(P29*PARÂMETROS!$B$4,2)) | R29: 10 | S29: 8889.93 | V29: =IF(T29="","",ROUND(T29*PARÂMETROS!$B$5,2)) | Y29: =IFERROR(ROUND(W29/T29,2),"") | Z29: =IFERROR(ROUND(N29/T29,2),"") | AA29: =IFERROR(ROUND(N29/W29,2),"") | AB29: 3.2 | AC29: 13144.01 | AD29: 8889.93 | AF29: Poste de Metálico Simplificado Deflexão máxima 1◦0"00" Fornecimento de Poste inclui gabaritos, peças, placa de identificação, parafusos e tudo o que for necessário para sua correta instalação, sempre galvanizado a quente (≥ 84micron, NBR 6323). >> 4
A30: 33 | B30: POSTE | C30: Poste Metálico Simplificado | E30: Poste Metálico Simplificado · 9m · AeV 4m² · 45m/s | F30: VB | H30: 4 | I30: 9 | J30: 4 | K30: 45 | L30: 5 | M30: 9627.7 | N30: =IF(M30="","",ROUND(M30*PARÂMETROS!$B$4,2)) | O30: 5 | P30: 9627.7 | Q30: =IF(P30="","",ROUND(P30*PARÂMETROS!$B$4,2)) | R30: 10 | S30: 9627.7 | V30: =IF(T30="","",ROUND(T30*PARÂMETROS!$B$5,2)) | Y30: =IFERROR(ROUND(W30/T30,2),"") | Z30: =IFERROR(ROUND(N30/T30,2),"") | AA30: =IFERROR(ROUND(N30/W30,2),"") | AB30: 3.1 | AC30: 13390.39 | AD30: 9627.7 | AF30: Poste de Metálico Simplificado Deflexão máxima 1◦0"00" Fornecimento de Poste inclui gabaritos, peças, placa de identificação, parafusos e tudo o que for necessário para sua correta instalação, sempre galvanizado a quente (≥ 84micron, NBR 6323). >> 4
A31: 34 | B31: POSTE | C31: Poste Metálico Simplificado | E31: Poste Metálico Simplificado · 9m · AeV 5m² · 30m/s | F31: VB | H31: 5 | I31: 9 | J31: 5 | K31: 30 | L31: 5 | M31: 8285.83 | N31: =IF(M31="","",ROUND(M31*PARÂMETROS!$B$4,2)) | O31: 5 | P31: 8285.83 | Q31: =IF(P31="","",ROUND(P31*PARÂMETROS!$B$4,2)) | R31: 10 | S31: 8285.83 | V31: =IF(T31="","",ROUND(T31*PARÂMETROS!$B$5,2)) | Y31: =IFERROR(ROUND(W31/T31,2),"") | Z31: =IFERROR(ROUND(N31/T31,2),"") | AA31: =IFERROR(ROUND(N31/W31,2),"") | AB31: 4.7 | AC31: 13314.78 | AD31: 8285.83 | AF31: Poste de Metálico Simplificado Deflexão máxima 1◦0"00" Fornecimento de Poste inclui gabaritos, peças, placa de identificação, parafusos e tudo o que for necessário para sua correta instalação, sempre galvanizado a quente (≥ 84micron, NBR 6323). >> 5
A32: 35 | B32: POSTE | C32: Poste Metálico Simplificado | E32: Poste Metálico Simplificado · 9m · AeV 5m² · 35m/s | F32: VB | H32: 5 | I32: 9 | J32: 5 | K32: 35 | L32: 5 | M32: 8700.12 | N32: =IF(M32="","",ROUND(M32*PARÂMETROS!$B$4,2)) | O32: 5 | P32: 8700.12 | Q32: =IF(P32="","",ROUND(P32*PARÂMETROS!$B$4,2)) | R32: 10 | S32: 8700.12 | V32: =IF(T32="","",ROUND(T32*PARÂMETROS!$B$5,2)) | Y32: =IFERROR(ROUND(W32/T32,2),"") | Z32: =IFERROR(ROUND(N32/T32,2),"") | AA32: =IFERROR(ROUND(N32/W32,2),"") | AB32: 4.7 | AC32: 13403.46 | AD32: 8700.12 | AF32: Poste de Metálico Simplificado Deflexão máxima 1◦0"00" Fornecimento de Poste inclui gabaritos, peças, placa de identificação, parafusos e tudo o que for necessário para sua correta instalação, sempre galvanizado a quente (≥ 84micron, NBR 6323). >> 5
A33: 36 | B33: POSTE | C33: Poste Metálico Simplificado | E33: Poste Metálico Simplificado · 9m · AeV 5m² · 40m/s | F33: VB | H33: 5 | I33: 9 | J33: 5 | K33: 40 | L33: 5 | M33: 9035.67 | N33: =IF(M33="","",ROUND(M33*PARÂMETROS!$B$4,2)) | O33: 5 | P33: 9035.67 | Q33: =IF(P33="","",ROUND(P33*PARÂMETROS!$B$4,2)) | R33: 10 | S33: 9035.67 | V33: =IF(T33="","",ROUND(T33*PARÂMETROS!$B$5,2)) | Y33: =IFERROR(ROUND(W33/T33,2),"") | Z33: =IFERROR(ROUND(N33/T33,2),"") | AA33: =IFERROR(ROUND(N33/W33,2),"") | AB33: 3.2 | AC33: 13947.27 | AD33: 9035.67 | AF33: Poste de Metálico Simplificado Deflexão máxima 1◦0"00" Fornecimento de Poste inclui gabaritos, peças, placa de identificação, parafusos e tudo o que for necessário para sua correta instalação, sempre galvanizado a quente (≥ 84micron, NBR 6323). >> 5
A34: 37 | B34: POSTE | C34: Poste Metálico Simplificado | E34: Poste Metálico Simplificado · 9m · AeV 5m² · 45m/s | F34: VB | H34: 5 | I34: 9 | J34: 5 | K34: 45 | L34: 5 | M34: 9785.53 | N34: =IF(M34="","",ROUND(M34*PARÂMETROS!$B$4,2)) | O34: 5 | P34: 9785.53 | Q34: =IF(P34="","",ROUND(P34*PARÂMETROS!$B$4,2)) | R34: 10 | S34: 9785.53 | V34: =IF(T34="","",ROUND(T34*PARÂMETROS!$B$5,2)) | Y34: =IFERROR(ROUND(W34/T34,2),"") | Z34: =IFERROR(ROUND(N34/T34,2),"") | AA34: =IFERROR(ROUND(N34/W34,2),"") | AB34: 3.1 | AC34: 14196.06 | AD34: 9785.53 | AF34: Poste de Metálico Simplificado Deflexão máxima 1◦0"00" Fornecimento de Poste inclui gabaritos, peças, placa de identificação, parafusos e tudo o que for necessário para sua correta instalação, sempre galvanizado a quente (≥ 84micron, NBR 6323). >> 5
A35: 38 | B35: POSTE | C35: Poste Metálico Simplificado | E35: Kit de ancoragem Poste 9m | F35: VB | I35: 9 | L35: 5 | M35: 1375 | N35: =IF(M35="","",ROUND(M35*PARÂMETROS!$B$4,2)) | O35: 5 | P35: 1375 | Q35: =IF(P35="","",ROUND(P35*PARÂMETROS!$B$4,2)) | R35: 10 | S35: 1375 | V35: =IF(T35="","",ROUND(T35*PARÂMETROS!$B$5,2)) | Y35: =IFERROR(ROUND(W35/T35,2),"") | Z35: =IFERROR(ROUND(N35/T35,2),"") | AA35: =IFERROR(ROUND(N35/W35,2),"") | AB35: 5.5 | AC35: 1550.57 | AD35: 1375 | AF35: Poste de Metálico Simplificado Deflexão máxima 1◦0"00" Fornecimento de Poste inclui gabaritos, peças, placa de identificação, parafusos e tudo o que for necessário para sua correta instalação, sempre galvanizado a quente (≥ 84micron, NBR 6323). >> Kit de ancoragem Poste 9m
A36: 39 | B36: POSTE | C36: Montagem Poste | E36: Montagem Poste | F36: VB | I36: 9 | L36: 5 | M36: 11631.09 | N36: =IF(M36="","",ROUND(M36*PARÂMETROS!$B$4,2)) | O36: 6 | P36: 12700.54 | Q36: =IF(P36="","",ROUND(P36*PARÂMETROS!$B$4,2)) | R36: 11 | S36: 11631.09 | V36: =IF(T36="","",ROUND(T36*PARÂMETROS!$B$5,2)) | Y36: =IFERROR(ROUND(W36/T36,2),"") | Z36: =IFERROR(ROUND(N36/T36,2),"") | AA36: =IFERROR(ROUND(N36/W36,2),"") | AB36: 5.7 | AC36: 14259.29 | AD36: 11631.09 | AF36: Montagem Poste >> Inclui mão de obra, equipamentos p/ içamento, ferramentas e o que for necessário para correta execução da montagem da EV.
A37: 40 | B37: MASTRO | C37: Mastro | E37: Mastro · 10m · AeV 3m² · 45m/s | F37: VB | G37: - | H37: 3 | I37: 10 | J37: 3 | K37: 45 | L37: 4 | M37: 33371.64 | N37: =IF(M37="","",ROUND(M37*PARÂMETROS!$B$4,2)) | O37: 4 | P37: 30427.16 | Q37: =IF(P37="","",ROUND(P37*PARÂMETROS!$B$4,2)) | R37: 8 | S37: 30427.16 | V37: =IF(T37="","",ROUND(T37*PARÂMETROS!$B$5,2)) | Y37: =IFERROR(ROUND(W37/T37,2),"") | Z37: =IFERROR(ROUND(N37/T37,2),"") | AA37: =IFERROR(ROUND(N37/W37,2),"") | AB37: 8.4 | AC37: 34744.96 | AD37: 28464.17 | AF37: Mastros Mastros com altura superior 2m deverão ser providos de pedaleira e cabo trava-quedas. >> 3
A38: 41 | B38: MASTRO | C38: Mastro | E38: Mastro · 10m · AeV 4m² · 45m/s | F38: VB | G38: - | H38: 4 | I38: 10 | J38: 4 | K38: 45 | L38: 4 | M38: 34598.51 | N38: =IF(M38="","",ROUND(M38*PARÂMETROS!$B$4,2)) | O38: 4 | P38: 31506.8 | Q38: =IF(P38="","",ROUND(P38*PARÂMETROS!$B$4,2)) | R38: 8 | S38: 31506.8 | V38: =IF(T38="","",ROUND(T38*PARÂMETROS!$B$5,2)) | Y38: =IFERROR(ROUND(W38/T38,2),"") | Z38: =IFERROR(ROUND(N38/T38,2),"") | AA38: =IFERROR(ROUND(N38/W38,2),"") | AB38: 9.8 | AC38: 37922.49 | AD38: 29445.67 | AF38: Mastros Mastros com altura superior 2m deverão ser providos de pedaleira e cabo trava-quedas. >> 4
A39: 42 | B39: POSTE | C39: Poste Concreto/Fibra Simplificado | E39: Balizamento Média Intensidade EV de 46 até 150m — 3 | F39: VB | I39: 12 | J39: 3 | K39: 30 | L39: 1 | M39: 4950 | N39: =IF(M39="","",ROUND(M39*PARÂMETROS!$B$4,2)) | O39: 1 | P39: 4950 | Q39: =IF(P39="","",ROUND(P39*PARÂMETROS!$B$4,2)) | R39: 2 | S39: 4950 | V39: =IF(T39="","",ROUND(T39*PARÂMETROS!$B$5,2)) | Y39: =IFERROR(ROUND(W39/T39,2),"") | Z39: =IFERROR(ROUND(N39/T39,2),"") | AA39: =IFERROR(ROUND(N39/W39,2),"") | AB39: 1 | AC39: 4950 | AD39: 4950 | AF39: Poste de Concreto ou Fibra Simplificado Deflexão máxima 1◦0"00" >> Balizamento Média Intensidade EV de 46 até 150m >> 3
A40: 43 | B40: POSTE | C40: Poste Concreto/Fibra Simplificado | D40: FCI | E40: 3 | F40: VB | I40: 12 | J40: 3 | K40: 35 | L40: 1 | M40: 5197.5 | N40: =IF(M40="","",ROUND(M40*PARÂMETROS!$B$4,2)) | O40: 1 | P40: 5197.5 | Q40: =IF(P40="","",ROUND(P40*PARÂMETROS!$B$4,2)) | R40: 2 | S40: 5197.5 | V40: =IF(T40="","",ROUND(T40*PARÂMETROS!$B$5,2)) | Y40: =IFERROR(ROUND(W40/T40,2),"") | Z40: =IFERROR(ROUND(N40/T40,2),"") | AA40: =IFERROR(ROUND(N40/W40,2),"") | AB40: 1 | AC40: 5197.5 | AD40: 5197.5 | AF40: Poste de Concreto ou Fibra Simplificado Deflexão máxima 1◦0"00" >> FCI >> 3
...

Sheet ABERTURA DE MERCADO
A1: Linha LPU | B1: Família | C1: Grupo | D1: Subgrupo | E1: Item | F1: Un. | G1: Região | H1: Fornecedor | I1: Valor unitário cotado (R$) | J1: Entra na mediana N+NE?
A2: 5 | B2: MASTRO | C2: Mastro | E2: Mastro · 2m · AeV 2m² · 45m/s | F2: VB | G2: NORTE | H2: METALALFA (NEGOCIADO) | I2: 1055.67 | J2: SIM
A3: 5 | B3: MASTRO | C3: Mastro | E3: Mastro · 2m · AeV 2m² · 45m/s | F3: VB | G3: NORTE | H3: BRASILSAT | I3: 3763.92 | J3: SIM
A4: 5 | B4: MASTRO | C4: Mastro | E4: Mastro · 2m · AeV 2m² · 45m/s | F4: VB | G4: NORTE | H4: CLEMAR (NEGOCIADO) | I4: 3840 | J4: SIM
A5: 5 | B5: MASTRO | C5: Mastro | E5: Mastro · 2m · AeV 2m² · 45m/s | F5: VB | G5: NORTE | H5: ZOPONE (NEGOCIADO) | I5: 6620.64 | J5: SIM
A6: 5 | B6: MASTRO | C6: Mastro | E6: Mastro · 2m · AeV 2m² · 45m/s | F6: VB | G6: NORDESTE | H6: METALALFA (NEGOCIADO) | I6: 1055.67 | J6: SIM
A7: 5 | B7: MASTRO | C7: Mastro | E7: Mastro · 2m · AeV 2m² · 45m/s | F7: VB | G7: NORDESTE | H7: CLEMAR (NEGOCIADO) | I7: 3680 | J7: SIM
A8: 5 | B8: MASTRO | C8: Mastro | E8: Mastro · 2m · AeV 2m² · 45m/s | F8: VB | G8: NORDESTE | H8: BRASILSAT | I8: 3763.92 | J8: SIM
A9: 5 | B9: MASTRO | C9: Mastro | E9: Mastro · 2m · AeV 2m² · 45m/s | F9: VB | G9: NORDESTE | H9: ZOPONE (NEGOCIADO) | I9: 5826.16 | J9: SIM
A10: 5 | B10: MASTRO | C10: Mastro | E10: Mastro · 2m · AeV 2m² · 45m/s | F10: VB | G10: C OESTE | H10: METALALFA (NEGOCIADO) | I10: 1055.67 | J10: não
A11: 5 | B11: MASTRO | C11: Mastro | E11: Mastro · 2m · AeV 2m² · 45m/s | F11: VB | G11: C OESTE | H11: CLEMAR (NEGOCIADO) | I11: 3680 | J11: não
A12: 5 | B12: MASTRO | C12: Mastro | E12: Mastro · 2m · AeV 2m² · 45m/s | F12: VB | G12: C OESTE | H12: BRASILSAT | I12: 3680.03 | J12: não
A13: 5 | B13: MASTRO | C13: Mastro | E13: Mastro · 2m · AeV 2m² · 45m/s | F13: VB | G13: C OESTE | H13: ZOPONE (NEGOCIADO) | I13: 6090.98 | J13: não
... A217: 13 | B217: MASTRO | C217: Mastro | E217: Mastro · 8m · AeV 4m² · 45m/s | F217: VB | G217: SUL | H217: CLEMAR (NEGOCIADO) | I217: 29706.6 | J217: não
A218: 14 | B218: POSTE | C218: Poste Concreto/Fibra Simplificado | D218: Suporte RF em plataforma EV > 30m | E218: 3 | F218: VB | G218: NORTE | H218: ZOPONE (NEGOCIADO) | I218: 3375 | J218: SIM
A219: 14 | B219: POSTE | C219: Poste Concreto/Fibra Simplificado | D219: Suporte RF em plataforma EV > 30m | E219: 3 | F219: VB | G219: NORDESTE | H219: ZOPONE (NEGOCIADO) | I219: 3375 | J219: SIM
A220: 14 | B220: POSTE | C220: Poste Concreto/Fibra Simplificado | D220: Suporte RF em plataforma EV > 30m | E220: 3 | F220: VB | G220: C OESTE | H220: ZOPONE (NEGOCIADO) | I220: 3375 | J220: não
A221: 14 | B221: POSTE | C221: Poste Concreto/Fibra Simplificado | D221: Suporte RF em plataforma EV > 30m | E221: 3 | F221: VB | G221: SÃO PAULO | H221: ZOPONE (NEGOCIADO) | I221: 3375 | J221: não
A222: 14 | B222: POSTE | C222: Poste Concreto/Fibra Simplificado | D222: Suporte RF em plataforma EV > 30m | E222: 3 | F222: VB | G222: LESTE | H222: ZOPONE (NEGOCIADO) | I222: 3375 | J222: não
A223: 14 | B223: POSTE | C223: Poste Concreto/Fibra Simplificado | D223: Suporte RF em plataforma EV > 30m | E223: 3 | F223: VB | G223: SUL | H223: ZOPONE (NEGOCIADO) | I223: 3375 | J223: não
A224: 15 | B224: POSTE | C224: Poste Concreto/Fibra Simplificado | D224: Suporte RF em plataforma EV > 30m | E224: 3 | F224: VB | G224: NORTE | H224: ZOPONE (NEGOCIADO) | I224: 3543.75 | J224: SIM
A225: 15 | B225: POSTE | C225: Poste Concreto/Fibra Simplificado | D225: Suporte RF em plataforma EV > 30m | E225: 3 | F225: VB | G225: NORDESTE | H225: ZOPONE (NEGOCIADO) | I225: 3543.75 | J225: SIM
A226: 15 | B226: POSTE | C226: Poste Concreto/Fibra Simplificado | D226: Suporte RF em plataforma EV > 30m | E226: 3 | F226: VB | G226: C OESTE | H226: ZOPONE (NEGOCIADO) | I226: 3543.75 | J226: não
A227: 15 | B227: POSTE | C227: Poste Concreto/Fibra Simplificado | D227: Suporte RF em plataforma EV > 30m | E227: 3 | F227: VB | G227: SÃO PAULO | H227: ZOPONE (NEGOCIADO) | I227: 3543.75 | J227: não
A228: 15 | B228: POSTE | C228: Poste Concreto/Fibra Simplificado | D228: Suporte RF em plataforma EV > 30m | E228: 3 | F228: VB | G228: LESTE | H228: ZOPONE (NEGOCIADO) | I228: 3543.75 | J228: não
A229: 15 | B229: POSTE | C229: Poste Concreto/Fibra Simplificado | D229: Suporte RF em plataforma EV > 30m | E229: 3 | F229: VB | G229: SUL | H229: ZOPONE (NEGOCIADO) | I229: 3543.75 | J229: não
... A241: 17 | B241: POSTE | C241: Poste Concreto/Fibra Simplificado | D241: SPDA | E241: 3 | F241: VB | G241: SUL | H241: ZOPONE (NEGOCIADO) | I241: 3906.98 | J241: não
A242: 18 | B242: POSTE | C242: Poste Concreto/Fibra Simplificado | E242: Poste Concreto/Fibra Simplificado · 9m · AeV 4m² · 30m/s | F242: VB | G242: NORTE | H242: ZOPONE (NEGOCIADO) | I242: 3881.25 | J242: SIM
A243: 18 | B243: POSTE | C243: Poste Concreto/Fibra Simplificado | E243: Poste Concreto/Fibra Simplificado · 9m · AeV 4m² · 30m/s | F243: VB | G243: NORDESTE | H243: ZOPONE (NEGOCIADO) | I243: 3881.25 | J243: SIM
A244: 18 | B244: POSTE | C244: Poste Concreto/Fibra Simplificado | E244: Poste Concreto/Fibra Simplificado · 9m · AeV 4m² · 30m/s | F244: VB | G244: C OESTE | H244: ZOPONE (NEGOCIADO) | I244: 3881.25 | J244: não
A245: 18 | B245: POSTE | C245: Poste Concreto/Fibra Simplificado | E245: Poste Concreto/Fibra Simplificado · 9m · AeV 4m² · 30m/s | F245: VB | G245: SÃO PAULO | H245: ZOPONE (NEGOCIADO) | I245: 3881.25 | J245: não
A246: 18 | B246: POSTE | C246: Poste Concreto/Fibra Simplificado | E246: Poste Concreto/Fibra Simplificado · 9m · AeV 4m² · 30m/s | F246: VB | G246: LESTE | H246: ZOPONE (NEGOCIADO) | I246: 3881.25 | J246: não
A247: 18 | B247: POSTE | C247: Poste Concreto/Fibra Simplificado | E247: Poste Concreto/Fibra Simplificado · 9m · AeV 4m² · 30m/s | F247: VB | G247: SUL | H247: ZOPONE (NEGOCIADO) | I247: 3881.25 | J247: não
A248: 19 | B248: POSTE | C248: Poste Concreto/Fibra Simplificado | D248: Escada EV > 30m | E248: 4 | F248: VB | G248: NORTE | H248: ZOPONE (NEGOCIADO) | I248: 4075.31 | J248: SIM
A249: 19 | B249: POSTE | C249: Poste Concreto/Fibra Simplificado | D249: Escada EV > 30m | E249: 4 | F249: VB | G249: NORDESTE | H249: ZOPONE (NEGOCIADO) | I249: 4075.31 | J249: SIM
A250: 19 | B250: POSTE | C250: Poste Concreto/Fibra Simplificado | D250: Escada EV > 30m | E250: 4 | F250: VB | G250: C OESTE | H250: ZOPONE (NEGOCIADO) | I250: 4075.31 | J250: não
A251: 19 | B251: POSTE | C251: Poste Concreto/Fibra Simplificado | D251: Escada EV > 30m | E251: 4 | F251: VB | G251: SÃO PAULO | H251: ZOPONE (NEGOCIADO) | I251: 4075.31 | J251: não
A252: 19 | B252: POSTE | C252: Poste Concreto/Fibra Simplificado | D252: Escada EV > 30m | E252: 4 | F252: VB | G252: LESTE | H252: ZOPONE (NEGOCIADO) | I252: 4075.31 | J252: não
A253: 19 | B253: POSTE | C253: Poste Concreto/Fibra Simplificado | D253: Escada EV > 30m | E253: 4 | F253: VB | G253: SUL | H253: ZOPONE (NEGOCIADO) | I253: 4075.31 | J253: não
A254: 20 | B254: POSTE | C254: Poste Concreto/Fibra Simplificado | D254: Trava quedas | E254: 4 | F254: VB | G254: NORTE | H254: ZOPONE (NEGOCIADO) | I254: 4279.08 | J254: SIM
...

Sheet LPU ADEQUAÇÃO
K1: C OESTE | Z1: NORDESTE | AU1: N O R T E | BN1: SÃO PAULO | CF1: LESTE (ES, MG E RJ) | CX1: SUL
K2: CLEMAR (NEGOCIADO) | M2: ZOPONE (NEGOCIADO) | O2: METALALFA (NEGOCIADO) | Q2: CAW (NEGOCIADO) | S2: BRASILSAT | U2: INFRASITE + SECCIONAL | W2: CAW ESTRUTURA + AGEPLAN OBRA | Z2: CLEMAR (NEGOCIADO) | AB2: NOVA CORRENTE | AD2: ZOPONE (NEGOCIADO) | AF2: METALALFA (NEGOCIADO) | AH2: CAW (NEGOCIADO) | AJ2: BRASILSAT | AL2: INFRASITE + SECCIONAL | AN2: CAW ESTRUTURA + AGEPLAN OBRA | AU2: VALOR MERCADO | AV2: MÉDIA | AX2: LS OFFICE | AZ2: CLEMAR (NEGOCIADO) | BB2: ZOPONE (NEGOCIADO) | BD2: METALALFA (NEGOCIADO) | BF2: CAW (NEGOCIADO) | BH2: BRASILSAT | BJ2: INFRASITE + SECCIONAL | BL2: CAW ESTRUTURA + AGEPLAN OBRA | BN2: CLEMAR (NEGOCIADO) | BP2: NOVA CORRENTE | BR2: ZOPONE (NEGOCIADO) | BT2: METALALFA (NEGOCIADO) | BV2: CAW (NEGOCIADO) | BX2: BRASILSAT | BZ2: INFRASITE + SECCIONAL | CB2: CAW ESTRUTURA + AGEPLAN OBRA | CF2: CLEMAR (NEGOCIADO) | CH2: NOVA CORRENTE | CJ2: ZOPONE (NEGOCIADO) | CL2: METALALFA (NEGOCIADO) | CN2: CAW (NEGOCIADO) | CP2: BRASILSAT | CR2: INFRASITE + SECCIONAL | CT2: CAW ESTRUTURA + AGEPLAN OBRA | CX2: CLEMAR (NEGOCIADO) | CZ2: NOVA CORRENTE | DB2: ZOPONE (NEGOCIADO) | DD2: METALALFA (NEGOCIADO) | DF2: CAW (NEGOCIADO) | DH2: BRASILSAT | DJ2: INFRASITE + SECCIONAL | DL2: CAW ESTRUTURA + AGEPLAN OBRA
B4: RESUMO | C4: SOLUÇÃO | D4: SIMPLES | E4: MACRO | F4: Altura (m) | G4: AeV c/ CA Nominal EV (m²) | H4: S1xV0 (m/s) | I4: Unid. | J4: QTDE | K4: Unitário | L4: Total | M4: Unitário2 | N4: Total3 | O4: Unitário4 | P4: Total5 | Q4: Unitário6 | R4: Total7 | S4: Unitário8 | T4: Total9 | U4: Unitário10 | V4: Total11 | W4: Unitário12 | X4: Total13 | Y4: 0 | Z4: Unitário14 | AA4: Total15 | AB4: Unitário16 | AC4: Total17 | AD4: Unitário18 | AE4: Total19 | AF4: Unitário20 | AG4: Total21 | AH4: Unitário22 | AI4: Total23 | AJ4: Unitário24 | AK4: Total25 | AL4: Unitário26 | AM4: Total27 | AN4: Unitário28 | AO4: Total29 | AP4: 1 | AQ4: 2 | AR4: 3 | AS4: 4 | AT4: 5 | AU4: VALOR MERCADO | AV4: VL UNIT MÉDIA | AW4: TOTAL MÉDIA | AX4: VL UNITÁRIO LS | AY4: TOTAL LS | AZ4: VL UNITÁRIO CLEMAR | BA4: TOTAL CLEMAR | BB4: Unitário32 | BC4: Total33 | BD4: Unitário34 | BE4: Total35 | BF4: Unitário36 | BG4: Total37 | BH4: Unitário38 | BI4: Total39 | BJ4: Unitário40 | BK4: Total41 | BL4: Unitário42 | BM4: Total43 | BN4: Unitário44 | BO4: Total45 | BP4: Unitário46 | BQ4: Total47 | BR4: Unitário48 | BS4: Total49 | BT4: Unitário50 | BU4: Total51 | BV4: Unitário52 | BW4: Total53 | BX4: Unitário54 | BY4: Total55 | BZ4: Unitário56 | CA4: Total57 | CB4: Unitário58 | CC4: Total59 | CD4: Minimo | CF4: Unitário | CG4: Total | CH4: Unitário | CI4: Total | CJ4: Unitário | CK4: Total | CL4: Unitário | CM4: Total | CN4: Unitário | CO4: Total | CP4: Unitário | CQ4: Total | CR4: Unitário | CS4: Total | CT4: Unitário | CU4: Total | CV4: Minimo | CX4: Unitário | CY4: Total | CZ4: Unitário | DA4: Total | DB4: Unitário | DC4: Total | DD4: Unitário | DE4: Total | DF4: Unitário | DG4: Total | DH4: Unitário | DI4: Total | DJ4: Unitário | DK4: Total | DL4: Unitário | DM4: Total | DN4: Minimo | DO4: Minimo
B5: MASTRO | C5: Mastros Mastros com altura superior 2m deverão ser providos de pedaleira e cabo trava-quedas. | D5: - | E5: 2 | F5: 2 | G5: 2 | H5: 45 | I5: VB | K5: 3680 | L5: =IF(ISTEXT(K5),K5,$J5*K5) | M5: 6090.98 | N5: =IF(ISTEXT(M5),M5,$J5*M5) | O5: 1055.6704 | P5: =IF(ISTEXT(O5),O5,$J5*O5) | Q5: n/a | R5: =IF(ISTEXT(Q5),Q5,$J5*Q5) | S5: 3680.0304 | T5: =IF(ISTEXT(S5),S5,$J5*S5) | U5: N/A | V5: =IF(ISTEXT(U5),U5,$J5*U5) | W5: N/A | X5: =IF(ISTEXT(W5),W5,$J5*W5) | Z5: 3680 | AA5: =IF(ISTEXT(Z5),Z5,$J5*Z5) | AB5: NA | AC5: =IF(ISTEXT(AB5),AB5,$J5*AB5) | AD5: 5826.16 | AE5: =IF(ISTEXT(AD5),AD5,$J5*AD5) | AF5: 1055.6704 | AG5: =IF(ISTEXT(AF5),AF5,$J5*AF5) | AH5: n/a | AI5: =IF(ISTEXT(AH5),AH5,$J5*AH5) | AJ5: 3763.9222 | AK5: =IF(ISTEXT(AJ5),AJ5,$J5*AJ5) | AL5: N/A | AM5: =IF(ISTEXT(AL5),AL5,$J5*AL5) | AN5: N/A | AO5: =IF(ISTEXT(AN5),AN5,$J5*AN5) | AU5: 3801.96 | AV5: =AVERAGE(AZ5,BB5,BD5,BF5,BH5,BJ5,BL5) | AW5: =BASEDADOS[[#This Row],[VL UNIT MÉDIA]]*BASEDADOS[[#This Row],[QTDE]] | AX5: =ROUND(AU5*PARÂMETROS!$B$4,2) | AZ5: 3840 | BA5: =IF(ISTEXT(AZ5),AZ5,$J5*AZ5) | BB5: 6620.64 | BC5: =IF(ISTEXT(BB5),BB5,$J5*BB5) | BD5: 1055.6704 | BE5: =IF(ISTEXT(BD5),BD5,$J5*BD5) | BF5: n/a | BG5: =IF(ISTEXT(BF5),BF5,$J5*BF5) | BH5: 3763.9222 | BI5: =IF(ISTEXT(BH5),BH5,$J5*BH5) | BJ5: N/A | BK5: =IF(ISTEXT(BJ5),BJ5,$J5*BJ5) | BL5: N/A | BM5: =IF(ISTEXT(BL5),BL5,$J5*BL5) | BN5: 3520 | BO5: =IF(ISTEXT(BN5),BN5,$J5*BN5) | BP5: NA | BQ5: =IF(ISTEXT(BP5),BP5,$J5*BP5) | BR5: 5296.51 | BS5: =IF(ISTEXT(BR5),BR5,$J5*BR5) | BT5: 1055.6704 | BU5: =IF(ISTEXT(BT5),BT5,$J5*BT5) | BV5: n/a | BW5: =IF(ISTEXT(BV5),BV5,$J5*BV5) | BX5: 3763.9222 | BY5: =IF(ISTEXT(BX5),BX5,$J5*BX5) | BZ5: N/A | CA5: =IF(ISTEXT(BZ5),BZ5,$J5*BZ5) | CB5: N/A | CC5: =IF(ISTEXT(CB5),CB5,$J5*CB5) | CD5: =IF($J5="",0,IF($J5=1,_xlfn.MINIFS(BN5:CC5,BN5:CC5,">"&0),_xlfn.MINIFS(BN5:CC5,BN5:CC5,">"&0,BN5:CC5,"<>"&BN5,BN5:CC5,"<>"&BP5,BN5:CC5,"<>"&BR5,BN5:CC5,"<>"&BT5,BN5:CC5,"<>"&BV5,BN5:CC5,"<>"&BX5,BN5:CC5,"<>"&BZ5,BN5:CC5,"<>"&CB5,BN5:CC5,"<>"&#REF!,BN5:CC5,"<>"&#REF!,BN5:CC5,"<>"&#REF!,BN5:CC5,"<>"&#REF!,BN5:CC5,"<>"&#REF!,BN5:CC5,"<>"&#REF!,BN5:CC5,"<>"&#REF!,BN5:CC5,"<>"&#REF!,BN5:CC5,"<>"&#REF!,BN5:CC5,"<>"&#REF!,BN5:CC5,"<>"&#REF!,BN5:CC5,"<>"&#REF!,BN5:CC5,"<>"&#REF!,BN5:CC5,"<>"&#REF!,BN5:CC5,"<>"&#REF!,BN5:CC5,"<>"&#REF!,BN5:CC5,"<>"&#REF!,BN5:CC5,"<>"&#REF!,BN5:CC5,"<>"&#REF!,BN5:CC5,"<>"&#REF!,BN5:CC5,"<>"&#REF!,BN5:CC5,"<>"&#REF!))) | CF5: 3360 | CG5: =IF(ISTEXT(CF5),CF5,$J5*CF5) | CH5: NA | CI5: =IF(ISTEXT(CH5),CH5,$J5*CH5) | CJ5: 5296.51 | CK5: =IF(ISTEXT(CJ5),CJ5,$J5*CJ5) | CL5: 1055.6704 | CM5: =IF(ISTEXT(CL5),CL5,$J5*CL5) | CN5: n/a | CO5: =IF(ISTEXT(CN5),CN5,$J5*CN5) | CP5: 3763.9222 | CQ5: =IF(ISTEXT(CP5),CP5,$J5*CP5) | CR5: N/A | CS5: =IF(ISTEXT(CR5),CR5,$J5*CR5) | CT5: N/A | CU5: =IF(ISTEXT(CT5),CT5,$J5*CT5) | CV5: =IF($J5="",0,IF($J5=1,_xlfn.MINIFS(CF5:CU5,CF5:CU5,">"&0),_xlfn.MINIFS(CF5:CU5,CF5:CU5,">"&0,CF5:CU5,"<>"&CF5,CF5:CU5,"<>"&CH5,CF5:CU5,"<>"&CJ5,CF5:CU5,"<>"&CL5,CF5:CU5,"<>"&CN5,CF5:CU5,"<>"&CP5,CF5:CU5,"<>"&CR5,CF5:CU5,"<>"&CT5,CF5:CU5,"<>"&#REF!,CF5:CU5,"<>"&#REF!,CF5:CU5,"<>"&#REF!,CF5:CU5,"<>"&#REF!,CF5:CU5,"<>"&#REF!,CF5:CU5,"<>"&#REF!,CF5:CU5,"<>"&#REF!,CF5:CU5,"<>"&#REF!,CF5:CU5,"<>"&#REF!,CF5:CU5,"<>"&#REF!,CF5:CU5,"<>"&#REF!,CF5:CU5,"<>"&#REF!,CF5:CU5,"<>"&#REF!,CF5:CU5,"<>"&#REF!,CF5:CU5,"<>"&#REF!,CF5:CU5,"<>"&#REF!,CF5:CU5,"<>"&#REF!,CF5:CU5,"<>"&#REF!,CF5:CU5,"<>"&#REF!,CF5:CU5,"<>"&#REF!,CF5:CU5,"<>"&#REF!,CF5:CU5,"<>"&#REF!))) | CX5: 3200 | CY5: =IF(ISTEXT(CX5),CX5,$J5*CX5) | CZ5: NA | DA5: =IF(ISTEXT(CZ5),CZ5,$J5*CZ5) | DB5: 5296.51 | DC5: =IF(ISTEXT(DB5),DB5,$J5*DB5) | DD5: 1055.6704 | DE5: =IF(ISTEXT(DD5),DD5,$J5*DD5) | DF5: n/a | DG5: =IF(ISTEXT(DF5),DF5,$J5*DF5) | DH5: 3763.9222 | DI5: =IF(ISTEXT(DH5),DH5,$J5*DH5) | DJ5: N/A | DK5: =IF(ISTEXT(DJ5),DJ5,$J5*DJ5) | DL5: N/A | DM5: =IF(ISTEXT(DL5),DL5,$J5*DL5) | DN5: =IF($J5="",0,IF($J5=1,_xlfn.MINIFS(CX5:DM5,CX5:DM5,">"&0),_xlfn.MINIFS(CX5:DM5,CX5:DM5,">"&0,CX5:DM5,"<>"&CX5,CX5:DM5,"<>"&CZ5,CX5:DM5,"<>"&DB5,CX5:DM5,"<>"&DD5,CX5:DM5,"<>"&DF5,CX5:DM5,"<>"&DH5,CX5:DM5,"<>"&DJ5,CX5:DM5,"<>"&DL5,CX5:DM5,"<>"&#REF!,CX5:DM5,"<>"&#REF!,CX5:DM5,"<>"&#REF!,CX5:DM5,"<>"&#REF!,CX5:DM5,"<>"&#REF!,CX5:DM5,"<>"&#REF!,CX5:DM5,"<>"&#REF!,CX5:DM5,"<>"&#REF!,CX5:DM5,"<>"&#REF!,CX5:DM5,"<>"&#REF!,CX5:DM5,"<>"&#REF!,CX5:DM5,"<>"&#REF!,CX5:DM5,"<>"&#REF!,CX5:DM5,"<>"&#REF!,CX5:DM5,"<>"&#REF!,CX5:DM5,"<>"&#REF!,CX5:DM5,"<>"&#REF!,CX5:DM5,"<>"&#REF!,CX5:DM5,"<>"&#REF!,CX5:DM5,"<>"&#REF!,CX5:DM5,"<>"&#REF!,CX5:DM5,"<>"&#REF!))) | DO5: =IF($J5="",0,IF($J5=1,_xlfn.MINIFS(#REF!,#REF!,">"&0),_xlfn.MINIFS(#REF!,#REF!,">"&0,#REF!,"<>"&#REF!,#REF!,"<>"&#REF!,#REF!,"<>"&#REF!,#REF!,"<>"&#REF!,#REF!,"<>"&#REF!,#REF!,"<>"&#REF!,#REF!,"<>"&#REF!,#REF!,"<>"&#REF!,#REF!,"<>"&#REF!,#REF!,"<>"&#REF!,#REF!,"<>"&#REF!,#REF!,"<>"&#REF!,#REF!,"<>"&#REF!,#REF!,"<>"&#REF!,#REF!,"<>"&#REF!,#REF!,"<>"&#REF!,#REF!,"<>"&#REF!,#REF!,"<>"&#REF!,#REF!,"<>"&#REF!,#REF!,"<>"&#REF!,#REF!,"<>"&#REF!,#REF!,"<>"&#REF!,#REF!,"<>"&#REF!,#REF!,"<>"&#REF!,#REF!,"<>"&#REF!,#REF!,"<>"&#REF!,#REF!,"<>"&#REF!,#REF!,"<>"&#REF!,#REF!,"<>"&#REF!,#REF!,"<>"&#REF!)))
B6: MASTRO | C6: Mastros Mastros com altura superior 2m deverão ser providos de pedaleira e cabo trava-quedas. | D6: - | E6: 2 | F6: 3 | G6: 2 | H6: 45 | I6: VB | K6: 7507.2 | L6: =IF(ISTEXT(K6),K6,$J6*K6) | M6: 12186.17 | N6: =IF(ISTEXT(M6),M6,$J6*M6) | O6: 2444.7104 | P6: =IF(ISTEXT(O6),O6,$J6*O6) | Q6: n/a | R6: =IF(ISTEXT(Q6),Q6,$J6*Q6) | S6: 4212.9948 | T6: =IF(ISTEXT(S6),S6,$J6*S6) | U6: N/A | V6: =IF(ISTEXT(U6),U6,$J6*U6) | W6: N/A | X6: =IF(ISTEXT(W6),W6,$J6*W6) | Z6: 7507.2 | AA6: =IF(ISTEXT(Z6),Z6,$J6*Z6) | AB6: NA | AC6: =IF(ISTEXT(AB6),AB6,$J6*AB6) | AD6: 11656.34 | AE6: =IF(ISTEXT(AD6),AD6,$J6*AD6) | AF6: 2444.7104 | AG6: =IF(ISTEXT(AF6),AF6,$J6*AF6) | AH6: n/a | AI6: =IF(ISTEXT(AH6),AH6,$J6*AH6) | AJ6: 4309.0363 | AK6: =IF(ISTEXT(AJ6),AJ6,$J6*AJ6) | AL6: N/A | AM6: =IF(ISTEXT(AL6),AL6,$J6*AL6) | AN6: N/A | AO6: =IF(ISTEXT(AN6),AN6,$J6*AN6) | AU6: 6071.32 | AV6: =AVERAGE(AZ6,BB6,BD6,BF6,BH6,BJ6,BL6) | AW6: =BASEDADOS[[#This Row],[VL UNIT MÉDIA]]*BASEDADOS[[#This Row],[QTDE]] | AX6: =ROUND(AU6*PARÂMETROS!$B$4,2) | AZ6: 7833.6 | BA6: =IF(ISTEXT(AZ6),AZ6,$J6*AZ6) | BB6: 13245.84 | BC6: =IF(ISTEXT(BB6),BB6,$J6*BB6) | BD6: 2444.7104 | BE6: =IF(ISTEXT(BD6),BD6,$J6*BD6) | BF6: n/a | BG6: =IF(ISTEXT(BF6),BF6,$J6*BF6) | BH6: 4309.0363 | BI6: =IF(ISTEXT(BH6),BH6,$J6*BH6) | BJ6: N/A | BK6: =IF(ISTEXT(BJ6),BJ6,$J6*BJ6) | BL6: N/A | BM6: =IF(ISTEXT(BL6),BL6,$J6*BL6) | BN6: 7180.8 | BO6: =IF(ISTEXT(BN6),BN6,$J6*BN6) | BP6: NA | BQ6: =IF(ISTEXT(BP6),BP6,$J6*BP6) | BR6: 10596.67 | BS6: =IF(ISTEXT(BR6),BR6,$J6*BR6) | BT6: 2444.7104 | BU6: =IF(ISTEXT(BT6),BT6,$J6*BT6) | BV6: n/a | BW6: =IF(ISTEXT(BV6),BV6,$J6*BV6) | BX6: 4309.0363 | BY6: =IF(ISTEXT(BX6),BX6,$J6*BX6) | BZ6: N/A | CA6: =IF(ISTEXT(BZ6),BZ6,$J6*BZ6) | CB6: N/A | CC6: =IF(ISTEXT(CB6),CB6,$J6*CB6) | CD6: =IF($J6="",0,IF($J6=1,_xlfn.MINIFS(BN6:CC6,BN6:CC6,">"&0),_xlfn.MINIFS(BN6:CC6,BN6:CC6,">"&0,BN6:CC6,"<>"&BN6,BN6:CC6,"<>"&BP6,BN6:CC6,"<>"&BR6,BN6:CC6,"<>"&BT6,BN6:CC6,"<>"&BV6,BN6:CC6,"<>"&BX6,BN6:CC6,"<>"&BZ6,BN6:CC6,"<>"&CB6,BN6:CC6,"<>"&#REF!,BN6:CC6,"<>"&#REF!,BN6:CC6,"<>"&#REF!,BN6:CC6,"<>"&#REF!,BN6:CC6,"<>"&#REF!,BN6:CC6,"<>"&#REF!,BN6:CC6,"<>"&#REF!,BN6:CC6,"<>"&#REF!,BN6:CC6,"<>"&#REF!,BN6:CC6,"<>"&#REF!,BN6:CC6,"<>"&#REF!,BN6:CC6,"<>"&#REF!,BN6:CC6,"<>"&#REF!,BN6:CC6,"<>"&#REF!,BN6:CC6,"<>"&#REF!,BN6:CC6,"<>"&#REF!,BN6:CC6,"<>"&#REF!,BN6:CC6,"<>"&#REF!,BN6:CC6,"<>"&#REF!,BN6:CC6,"<>"&#REF!,BN6:CC6,"<>"&#REF!,BN6:CC6,"<>"&#REF!))) | CF6: 6854.4 | CG6: =IF(ISTEXT(CF6),CF6,$J6*CF6) | CH6: NA | CI6: =IF(ISTEXT(CH6),CH6,$J6*CH6) | CJ6: 10596.67 | CK6: =IF(ISTEXT(CJ6),CJ6,$J6*CJ6) | CL6: 2444.7104 | CM6: =IF(ISTEXT(CL6),CL6,$J6*CL6) | CN6: n/a | CO6: =IF(ISTEXT(CN6),CN6,$J6*CN6) | CP6: 4309.0363 | CQ6: =IF(ISTEXT(CP6),CP6,$J6*CP6) | CR6: N/A | CS6: =IF(ISTEXT(CR6),CR6,$J6*CR6) | CT6: N/A | CU6: =IF(ISTEXT(CT6),CT6,$J6*CT6) | CV6: =IF($J6="",0,IF($J6=1,_xlfn.MINIFS(CF6:CU6,CF6:CU6,">"&0),_xlfn.MINIFS(CF6:CU6,CF6:CU6,">"&0,CF6:CU6,"<>"&CF6,CF6:CU6,"<>"&CH6,CF6:CU6,"<>"&CJ6,CF6:CU6,"<>"&CL6,CF6:CU6,"<>"&CN6,CF6:CU6,"<>"&CP6,CF6:CU6,"<>"&CR6,CF6:CU6,"<>"&CT6,CF6:CU6,"<>"&#REF!,CF6:CU6,"<>"&#REF!,CF6:CU6,"<>"&#REF!,CF6:CU6,"<>"&#REF!,CF6:CU6,"<>"&#REF!,CF6:CU6,"<>"&#REF!,CF6:CU6,"<>"&#REF!,CF6:CU6,"<>"&#REF!,CF6:CU6,"<>"&#REF!,CF6:CU6,"<>"&#REF!,CF6:CU6,"<>"&#REF!,CF6:CU6,"<>"&#REF!,CF6:CU6,"<>"&#REF!,CF6:CU6,"<>"&#REF!,CF6:CU6,"<>"&#REF!,CF6:CU6,"<>"&#REF!,CF6:CU6,"<>"&#REF!,CF6:CU6,"<>"&#REF!,CF6:CU6,"<>"&#REF!,CF6:CU6,"<>"&#REF!,CF6:CU6,"<>"&#REF!,CF6:CU6,"<>"&#REF!))) | CX6: 6528 | CY6: =IF(ISTEXT(CX6),CX6,$J6*CX6) | CZ6: NA | DA6: =IF(ISTEXT(CZ6),CZ6,$J6*CZ6) | DB6: 10596.67 | DC6: =IF(ISTEXT(DB6),DB6,$J6*DB6) | DD6: 2444.7104 | DE6: =IF(ISTEXT(DD6),DD6,$J6*DD6) | DF6: n/a | DG6: =IF(ISTEXT(DF6),DF6,$J6*DF6) | DH6: 4309.0363 | DI6: =IF(ISTEXT(DH6),DH6,$J6*DH6) | DJ6: N/A | DK6: =IF(ISTEXT(DJ6),DJ6,$J6*DJ6) | DL6: N/A | DM6: =IF(ISTEXT(DL6),DL6,$J6*DL6) | DN6: =IF($J6="",0,IF($J6=1,_xlfn.MINIFS(CX6:DM6,CX6:DM6,">"&0),_xlfn.MINIFS(CX6:DM6,CX6:DM6,">"&0,CX6:DM6,"<>"&CX6,CX6:DM6,"<>"&CZ6,CX6:DM6,"<>"&DB6,CX6:DM6,"<>"&DD6,CX6:DM6,"<>"&DF6,CX6:DM6,"<>"&DH6,CX6:DM6,"<>"&DJ6,CX6:DM6,"<>"&DL6,CX6:DM6,"<>"&#REF!,CX6:DM6,"<>"&#REF!,CX6:DM6,"<>"&#REF!,CX6:DM6,"<>"&#REF!,CX6:DM6,"<>"&#REF!,CX6:DM6,"<>"&#REF!,CX6:DM6,"<>"&#REF!,CX6:DM6,"<>"&#REF!,CX6:DM6,"<>"&#REF!,CX6:DM6,"<>"&#REF!,CX6:DM6,"<>"&#REF!,CX6:DM6,"<>"&#REF!,CX6:DM6,"<>"&#REF!,CX6:DM6,"<>"&#REF!,CX6:DM6,"<>"&#REF!,CX6:DM6,"<>"&#REF!,CX6:DM6,"<>"&#REF!,CX6:DM6,"<>"&#REF!,CX6:DM6,"<>"&#REF!,CX6:DM6,"<>"&#REF!,CX6:DM6,"<>"&#REF!,CX6:DM6,"<>"&#REF!))) | DO6: =IF($J6="",0,IF($J6=1,_xlfn.MINIFS(#REF!,#REF!,">"&0),_xlfn.MINIFS(#REF!,#REF!,">"&0,#REF!,"<>"&#REF!,#REF!,"<>"&#REF!,#REF!,"<>"&#REF!,#REF!,"<>"&#REF!,#REF!,"<>"&#REF!,#REF!,"<>"&#REF!,#REF!,"<>"&#REF!,#REF!,"<>"&#REF!,#REF!,"<>"&#REF!,#REF!,"<>"&#REF!,#REF!,"<>"&#REF!,#REF!,"<>"&#REF!,#REF!,"<>"&#REF!,#REF!,"<>"&#REF!,#REF!,"<>"&#REF!,#REF!,"<>"&#REF!,#REF!,"<>"&#REF!,#REF!,"<>"&#REF!,#REF!,"<>"&#REF!,#REF!,"<>"&#REF!,#REF!,"<>"&#REF!,#REF!,"<>"&#REF!,#REF!,"<>"&#REF!,#REF!,"<>"&#REF!,#REF!,"<>"&#REF!,#REF!,"<>"&#REF!,#REF!,"<>"&#REF!,#REF!,"<>"&#REF!,#REF!,"<>"&#REF!,#REF!,"<>"&#REF!)))
B7: MASTRO | C7: Mastros Mastros com altura superior 2m deverão ser providos de pedaleira e cabo trava-quedas. | D7: - | E7: 3 | F7: 3 | G7: 3 | H7: 45 | I7: VB | K7: 8096 | L7: =IF(ISTEXT(K7),K7,$J7*K7) | M7: 12795.48 | N7: =IF(ISTEXT(M7),M7,$J7*M7) | O7: 2444.7104 | P7: =IF(ISTEXT(O7),O7,$J7*O7) | Q7: n/a | R7: =IF(ISTEXT(Q7),Q7,$J7*Q7) | S7: 4212.9948 | T7: =IF(ISTEXT(S7),S7,$J7*S7) | U7: N/A | V7: =IF(ISTEXT(U7),U7,$J7*U7) | W7: N/A | X7: =IF(ISTEXT(W7),W7,$J7*W7) | Z7: 8096 | AA7: =IF(ISTEXT(Z7),Z7,$J7*Z7) | AB7: NA | AC7: =IF(ISTEXT(AB7),AB7,$J7*AB7) | AD7: 12239.15 | AE7: =IF(ISTEXT(AD7),AD7,$J7*AD7) | AF7: 2444.7104 | AG7: =IF(ISTEXT(AF7),AF7,$J7*AF7) | AH7: n/a | AI7: =IF(ISTEXT(AH7),AH7,$J7*AH7) | AJ7: 4309.0363 | AK7: =IF(ISTEXT(AJ7),AJ7,$J7*AJ7) | AL7: N/A | AM7: =IF(ISTEXT(AL7),AL7,$J7*AL7) | AN7: N/A | AO7: =IF(ISTEXT(AN7),AN7,$J7*AN7) | AU7: 6378.52 | AV7: =AVERAGE(AZ7,BB7,BD7,BF7,BH7,BJ7,BL7) | AW7: =BASEDADOS[[#This Row],[VL UNIT MÉDIA]]*BASEDADOS[[#This Row],[QTDE]] | AX7: =ROUND(AU7*PARÂMETROS!$B$4,2) | AZ7: 8448 | BA7: =IF(ISTEXT(AZ7),AZ7,$J7*AZ7) | BB7: 13908.13 | BC7: =IF(ISTEXT(BB7),BB7,$J7*BB7) | BD7: 2444.7104 | BE7: =IF(ISTEXT(BD7),BD7,$J7*BD7) | BF7: n/a | BG7: =IF(ISTEXT(BF7),BF7,$J7*BF7) | BH7: 4309.0363 | BI7: =IF(ISTEXT(BH7),BH7,$J7*BH7) | BJ7: N/A | BK7: =IF(ISTEXT(BJ7),BJ7,$J7*BJ7) | BL7: N/A | BM7: =IF(ISTEXT(BL7),BL7,$J7*BL7) | BN7: 7744 | BO7: =IF(ISTEXT(BN7),BN7,$J7*BN7) | BP7: NA | BQ7: =IF(ISTEXT(BP7),BP7,$J7*BP7) | BR7: 11126.5 | BS7: =IF(ISTEXT(BR7),BR7,$J7*BR7) | BT7: 2444.7104 | BU7: =IF(ISTEXT(BT7),BT7,$J7*BT7) | BV7: n/a | BW7: =IF(ISTEXT(BV7),BV7,$J7*BV7) | BX7: 4309.0363 | BY7: =IF(ISTEXT(BX7),BX7,$J7*BX7) | BZ7: N/A | CA7: =IF(ISTEXT(BZ7),BZ7,$J7*BZ7) | CB7: N/A | CC7: =IF(ISTEXT(CB7),CB7,$J7*CB7) | CD7: =IF($J7="",0,IF($J7=1,_xlfn.MINIFS(BN7:CC7,BN7:CC7,">"&0),_xlfn.MINIFS(BN7:CC7,BN7:CC7,">"&0,BN7:CC7,"<>"&BN7,BN7:CC7,"<>"&BP7,BN7:CC7,"<>"&BR7,BN7:CC7,"<>"&BT7,BN7:CC7,"<>"&BV7,BN7:CC7,"<>"&BX7,BN7:CC7,"<>"&BZ7,BN7:CC7,"<>"&CB7,BN7:CC7,"<>"&#REF!,BN7:CC7,"<>"&#REF!,BN7:CC7,"<>"&#REF!,BN7:CC7,"<>"&#REF!,BN7:CC7,"<>"&#REF!,BN7:CC7,"<>"&#REF!,BN7:CC7,"<>"&#REF!,BN7:CC7,"<>"&#REF!,BN7:CC7,"<>"&#REF!,BN7:CC7,"<>"&#REF!,BN7:CC7,"<>"&#REF!,BN7:CC7,"<>"&#REF!,BN7:CC7,"<>"&#REF!,BN7:CC7,"<>"&#REF!,BN7:CC7,"<>"&#REF!,BN7:CC7,"<>"&#REF!,BN7:CC7,"<>"&#REF!,BN7:CC7,"<>"&#REF!,BN7:CC7,"<>"&#REF!,BN7:CC7,"<>"&#REF!,BN7:CC7,"<>"&#REF!,BN7:CC7,"<>"&#REF!))) | CF7: 7392 | CG7: =IF(ISTEXT(CF7),CF7,$J7*CF7) | CH7: NA | CI7: =IF(ISTEXT(CH7),CH7,$J7*CH7) | CJ7: 11126.5 | CK7: =IF(ISTEXT(CJ7),CJ7,$J7*CJ7) | CL7: 2444.7104 | CM7: =IF(ISTEXT(CL7),CL7,$J7*CL7) | CN7: n/a | CO7: =IF(ISTEXT(CN7),CN7,$J7*CN7) | CP7: 4309.0363 | CQ7: =IF(ISTEXT(CP7),CP7,$J7*CP7) | CR7: N/A | CS7: =IF(ISTEXT(CR7),CR7,$J7*CR7) | CT7: N/A | CU7: =IF(ISTEXT(CT7),CT7,$J7*CT7) | CV7: =IF($J7="",0,IF($J7=1,_xlfn.MINIFS(CF7:CU7,CF7:CU7,">"&0),_xlfn.MINIFS(CF7:CU7,CF7:CU7,">"&0,CF7:CU7,"<>"&CF7,CF7:CU7,"<>"&CH7,CF7:CU7,"<>"&CJ7,CF7:CU7,"<>"&CL7,CF7:CU7,"<>"&CN7,CF7:CU7,"<>"&CP7,CF7:CU7,"<>"&CR7,CF7:CU7,"<>"&CT7,CF7:CU7,"<>"&#REF!,CF7:CU7,"<>"&#REF!,CF7:CU7,"<>"&#REF!,CF7:CU7,"<>"&#REF!,CF7:CU7,"<>"&#REF!,CF7:CU7,"<>"&#REF!,CF7:CU7,"<>"&#REF!,CF7:CU7,"<>"&#REF!,CF7:CU7,"<>"&#REF!,CF7:CU7,"<>"&#REF!,CF7:CU7,"<>"&#REF!,CF7:CU7,"<>"&#REF!,CF7:CU7,"<>"&#REF!,CF7:CU7,"<>"&#REF!,CF7:CU7,"<>"&#REF!,CF7:CU7,"<>"&#REF!,CF7:CU7,"<>"&#REF!,CF7:CU7,"<>"&#REF!,CF7:CU7,"<>"&#REF!,CF7:CU7,"<>"&#REF!,CF7:CU7,"<>"&#REF!,CF7:CU7,"<>"&#REF!))) | CX7: 7040 | CY7: =IF(ISTEXT(CX7),CX7,$J7*CX7) | CZ7: NA | DA7: =IF(ISTEXT(CZ7),CZ7,$J7*CZ7) | DB7: 11126.5 | DC7: =IF(ISTEXT(DB7),DB7,$J7*DB7) | DD7: 2444.7104 | DE7: =IF(ISTEXT(DD7),DD7,$J7*DD7) | DF7: n/a | DG7: =IF(ISTEXT(DF7),DF7,$J7*DF7) | DH7: 4309.0363 | DI7: =IF(ISTEXT(DH7),DH7,$J7*DH7) | DJ7: N/A | DK7: =IF(ISTEXT(DJ7),DJ7,$J7*DJ7) | DL7: N/A | DM7: =IF(ISTEXT(DL7),DL7,$J7*DL7) | DN7: =IF($J7="",0,IF($J7=1,_xlfn.MINIFS(CX7:DM7,CX7:DM7,">"&0),_xlfn.MINIFS(CX7:DM7,CX7:DM7,">"&0,CX7:DM7,"<>"&CX7,CX7:DM7,"<>"&CZ7,CX7:DM7,"<>"&DB7,CX7:DM7,"<>"&DD7,CX7:DM7,"<>"&DF7,CX7:DM7,"<>"&DH7,CX7:DM7,"<>"&DJ7,CX7:DM7,"<>"&DL7,CX7:DM7,"<>"&#REF!,CX7:DM7,"<>"&#REF!,CX7:DM7,"<>"&#REF!,CX7:DM7,"<>"&#REF!,CX7:DM7,"<>"&#REF!,CX7:DM7,"<>"&#REF!,CX7:DM7,"<>"&#REF!,CX7:DM7,"<>"&#REF!,CX7:DM7,"<>"&#REF!,CX7:DM7,"<>"&#REF!,CX7:DM7,"<>"&#REF!,CX7:DM7,"<>"&#REF!,CX7:DM7,"<>"&#REF!,CX7:DM7,"<>"&#REF!,CX7:DM7,"<>"&#REF!,CX7:DM7,"<>"&#REF!,CX7:DM7,"<>"&#REF!,CX7:DM7,"<>"&#REF!,CX7:DM7,"<>"&#REF!,CX7:DM7,"<>"&#REF!,CX7:DM7,"<>"&#REF!,CX7:DM7,"<>"&#REF!))) | DO7: =IF($J7="",0,IF($J7=1,_xlfn.MINIFS(#REF!,#REF!,">"&0),_xlfn.MINIFS(#REF!,#REF!,">"&0,#REF!,"<>"&#REF!,#REF!,"<>"&#REF!,#REF!,"<>"&#REF!,#REF!,"<>"&#REF!,#REF!,"<>"&#REF!,#REF!,"<>"&#REF!,#REF!,"<>"&#REF!,#REF!,"<>"&#REF!,#REF!,"<>"&#REF!,#REF!,"<>"&#REF!,#REF!,"<>"&#REF!,#REF!,"<>"&#REF!,#REF!,"<>"&#REF!,#REF!,"<>"&#REF!,#REF!,"<>"&#REF!,#REF!,"<>"&#REF!,#REF!,"<>"&#REF!,#REF!,"<>"&#REF!,#REF!,"<>"&#REF!,#REF!,"<>"&#REF!,#REF!,"<>"&#REF!,#REF!,"<>"&#REF!,#REF!,"<>"&#REF!,#REF!,"<>"&#REF!,#REF!,"<>"&#REF!,#REF!,"<>"&#REF!,#REF!,"<>"&#REF!,#REF!,"<>"&#REF!,#REF!,"<>"&#REF!,#REF!,"<>"&#REF!)))
B8: MASTRO | C8: Mastros Mastros com altura superior 2m deverão ser providos de pedaleira e cabo trava-quedas. | D8: - | E8: 2 | F8: 4 | G8: 2 | H8: 45 | I8: VB | K8: 9200 | L8: =IF(ISTEXT(K8),K8,$J8*K8) | M8: 13915.53 | N8: =IF(ISTEXT(M8),M8,$J8*M8) | O8: 6222.8992 | P8: =IF(ISTEXT(O8),O8,$J8*O8) | Q8: n/a | R8: =IF(ISTEXT(Q8),Q8,$J8*Q8) | S8: 4212.9948 | T8: =IF(ISTEXT(S8),S8,$J8*S8) | U8: N/A | V8: =IF(ISTEXT(U8),U8,$J8*U8) | W8: N/A | X8: =IF(ISTEXT(W8),W8,$J8*W8) | Z8: 9200 | AA8: =IF(ISTEXT(Z8),Z8,$J8*Z8) | AB8: NA | AC8: =IF(ISTEXT(AB8),AB8,$J8*AB8) | AD8: 13310.51 | AE8: =IF(ISTEXT(AD8),AD8,$J8*AD8) | AF8: 6222.8992 | AG8: =IF(ISTEXT(AF8),AF8,$J8*AF8) | AH8: n/a | AI8: =IF(ISTEXT(AH8),AH8,$J8*AH8) | AJ8: 4309.0363 | AK8: =IF(ISTEXT(AJ8),AJ8,$J8*AJ8) | AL8: N/A | AM8: =IF(ISTEXT(AL8),AL8,$J8*AL8) | AN8: N/A | AO8: =IF(ISTEXT(AN8),AN8,$J8*AN8) | AU8: 7911.45 | AV8: =AVERAGE(AZ8,BB8,BD8,BF8,BH8,BJ8,BL8) | AW8: =BASEDADOS[[#This Row],[VL UNIT MÉDIA]]*BASEDADOS[[#This Row],[QTDE]] | AX8: =ROUND(AU8*PARÂMETROS!$B$4,2) | AZ8: 9600 | BA8: =IF(ISTEXT(AZ8),AZ8,$J8*AZ8) | BB8: 15125.58 | BC8: =IF(ISTEXT(BB8),BB8,$J8*BB8) | BD8: 6222.8992 | BE8: =IF(ISTEXT(BD8),BD8,$J8*BD8) | BF8: n/a | BG8: =IF(ISTEXT(BF8),BF8,$J8*BF8) | BH8: 4309.0363 | BI8: =IF(ISTEXT(BH8),BH8,$J8*BH8) | BJ8: N/A | BK8: =IF(ISTEXT(BJ8),BJ8,$J8*BJ8) | BL8: N/A | BM8: =IF(ISTEXT(BL8),BL8,$J8*BL8) | BN8: 8800 | BO8: =IF(ISTEXT(BN8),BN8,$J8*BN8) | BP8: NA | BQ8: =IF(ISTEXT(BP8),BP8,$J8*BP8) | BR8: 12100.46 | BS8: =IF(ISTEXT(BR8),BR8,$J8*BR8) | BT8: 6222.8992 | BU8: =IF(ISTEXT(BT8),BT8,$J8*BT8) | BV8: n/a | BW8: =IF(ISTEXT(BV8),BV8,$J8*BV8) | BX8: 4309.0363 | BY8: =IF(ISTEXT(BX8),BX8,$J8*BX8) | BZ8: N/A | CA8: =IF(ISTEXT(BZ8),BZ8,$J8*BZ8) | CB8: N/A | CC8: =IF(ISTEXT(CB8),CB8,$J8*CB8) | CD8: =IF($J8="",0,IF($J8=1,_xlfn.MINIFS(BN8:CC8,BN8:CC8,">"&0),_xlfn.MINIFS(BN8:CC8,BN8:CC8,">"&0,BN8:CC8,"<>"&BN8,BN8:CC8,"<>"&BP8,BN8:CC8,"<>"&BR8,BN8:CC8,"<>"&BT8,BN8:CC8,"<>"&BV8,BN8:CC8,"<>"&BX8,BN8:CC8,"<>"&BZ8,BN8:CC8,"<>"&CB8,BN8:CC8,"<>"&#REF!,BN8:CC8,"<>"&#REF!,BN8:CC8,"<>"&#REF!,BN8:CC8,"<>"&#REF!,BN8:CC8,"<>"&#REF!,BN8:CC8,"<>"&#REF!,BN8:CC8,"<>"&#REF!,BN8:CC8,"<>"&#REF!,BN8:CC8,"<>"&#REF!,BN8:CC8,"<>"&#REF!,BN8:CC8,"<>"&#REF!,BN8:CC8,"<>"&#REF!,BN8:CC8,"<>"&#REF!,BN8:CC8,"<>"&#REF!,BN8:CC8,"<>"&#REF!,BN8:CC8,"<>"&#REF!,BN8:CC8,"<>"&#REF!,BN8:CC8,"<>"&#REF!,BN8:CC8,"<>"&#REF!,BN8:CC8,"<>"&#REF!,BN8:CC8,"<>"&#REF!,BN8:CC8,"<>"&#REF!))) | CF8: 8400 | CG8: =IF(ISTEXT(CF8),CF8,$J8*CF8) | CH8: NA | CI8: =IF(ISTEXT(CH8),CH8,$J8*CH8) | CJ8: 12100.46 | CK8: =IF(ISTEXT(CJ8),CJ8,$J8*CJ8) | CL8: 6222.8992 | CM8: =IF(ISTEXT(CL8),CL8,$J8*CL8) | CN8: n/a | CO8: =IF(ISTEXT(CN8),CN8,$J8*CN8) | CP8: 4309.0363 | CQ8: =IF(ISTEXT(CP8),CP8,$J8*CP8) | CR8: N/A | CS8: =IF(ISTEXT(CR8),CR8,$J8*CR8) | CT8: N/A | CU8: =IF(ISTEXT(CT8),CT8,$J8*CT8) | CV8: =IF($J8="",0,IF($J8=1,_xlfn.MINIFS(CF8:CU8,CF8:CU8,">"&0),_xlfn.MINIFS(CF8:CU8,CF8:CU8,">"&0,CF8:CU8,"<>"&CF8,CF8:CU8,"<>"&CH8,CF8:CU8,"<>"&CJ8,CF8:CU8,"<>"&CL8,CF8:CU8,"<>"&CN8,CF8:CU8,"<>"&CP8,CF8:CU8,"<>"&CR8,CF8:CU8,"<>"&CT8,CF8:CU8,"<>"&#REF!,CF8:CU8,"<>"&#REF!,CF8:CU8,"<>"&#REF!,CF8:CU8,"<>"&#REF!,CF8:CU8,"<>"&#REF!,CF8:CU8,"<>"&#REF!,CF8:CU8,"<>"&#REF!,CF8:CU8,"<>"&#REF!,CF8:CU8,"<>"&#REF!,CF8:CU8,"<>"&#REF!,CF8:CU8,"<>"&#REF!,CF8:CU8,"<>"&#REF!,CF8:CU8,"<>"&#REF!,CF8:CU8,"<>"&#REF!,CF8:CU8,"<>"&#REF!,CF8:CU8,"<>"&#REF!,CF8:CU8,"<>"&#REF!,CF8:CU8,"<>"&#REF!,CF8:CU8,"<>"&#REF!,CF8:CU8,"<>"&#REF!,CF8:CU8,"<>"&#REF!,CF8:CU8,"<>"&#REF!))) | CX8: 8000 | CY8: =IF(ISTEXT(CX8),CX8,$J8*CX8) | CZ8: NA | DA8: =IF(ISTEXT(CZ8),CZ8,$J8*CZ8) | DB8: 12100.46 | DC8: =IF(ISTEXT(DB8),DB8,$J8*DB8) | DD8: 6222.8992 | DE8: =IF(ISTEXT(DD8),DD8,$J8*DD8) | DF8: n/a | DG8: =IF(ISTEXT(DF8),DF8,$J8*DF8) | DH8: 4309.0363 | DI8: =IF(ISTEXT(DH8),DH8,$J8*DH8) | DJ8: N/A | DK8: =IF(ISTEXT(DJ8),DJ8,$J8*DJ8) | DL8: N/A | DM8: =IF(ISTEXT(DL8),DL8,$J8*DL8) | DN8: =IF($J8="",0,IF($J8=1,_xlfn.MINIFS(CX8:DM8,CX8:DM8,">"&0),_xlfn.MINIFS(CX8:DM8,CX8:DM8,">"&0,CX8:DM8,"<>"&CX8,CX8:DM8,"<>"&CZ8,CX8:DM8,"<>"&DB8,CX8:DM8,"<>"&DD8,CX8:DM8,"<>"&DF8,CX8:DM8,"<>"&DH8,CX8:DM8,"<>"&DJ8,CX8:DM8,"<>"&DL8,CX8:DM8,"<>"&#REF!,CX8:DM8,"<>"&#REF!,CX8:DM8,"<>"&#REF!,CX8:DM8,"<>"&#REF!,CX8:DM8,"<>"&#REF!,CX8:DM8,"<>"&#REF!,CX8:DM8,"<>"&#REF!,CX8:DM8,"<>"&#REF!,CX8:DM8,"<>"&#REF!,CX8:DM8,"<>"&#REF!,CX8:DM8,"<>"&#REF!,CX8:DM8,"<>"&#REF!,CX8:DM8,"<>"&#REF!,CX8:DM8,"<>"&#REF!,CX8:DM8,"<>"&#REF!,CX8:DM8,"<>"&#REF!,CX8:DM8,"<>"&#REF!,CX8:DM8,"<>"&#REF!,CX8:DM8,"<>"&#REF!,CX8:DM8,"<>"&#REF!,CX8:DM8,"<>"&#REF!,CX8:DM8,"<>"&#REF!))) | DO8: =IF($J8="",0,IF($J8=1,_xlfn.MINIFS(#REF!,#REF!,">"&0),_xlfn.MINIFS(#REF!,#REF!,">"&0,#REF!,"<>"&#REF!,#REF!,"<>"&#REF!,#REF!,"<>"&#REF!,#REF!,"<>"&#REF!,#REF!,"<>"&#REF!,#REF!,"<>"&#REF!,#REF!,"<>"&#REF!,#REF!,"<>"&#REF!,#REF!,"<>"&#REF!,#REF!,"<>"&#REF!,#REF!,"<>"&#REF!,#REF!,"<>"&#REF!,#REF!,"<>"&#REF!,#REF!,"<>"&#REF!,#REF!,"<>"&#REF!,#REF!,"<>"&#REF!,#REF!,"<>"&#REF!,#REF!,"<>"&#REF!,#REF!,"<>"&#REF!,#REF!,"<>"&#REF!,#REF!,"<>"&#REF!,#REF!,"<>"&#REF!,#REF!,"<>"&#REF!,#REF!,"<>"&#REF!,#REF!,"<>"&#REF!,#REF!,"<>"&#REF!,#REF!,"<>"&#REF!,#REF!,"<>"&#REF!,#REF!,"<>"&#REF!,#REF!,"<>"&#REF!)))
