Workbook

Sheet Layout
D7: Data | E7: 46089 | F7: =IF(E7="","PREENCHIMENTO OBRIGATÓRIO","")
D8: ID Highline | E8: PE4-SDM-002 | F8: =IF(E8="","PREENCHIMENTO OBRIGATÓRIO","")
D9: Região | E9: Nordeste | F9: =IF(E9="","PREENCHIMENTO OBRIGATÓRIO","")
D10: PM / Coordenador | E10: Vinicius Barbieri | F10: =IF(E10="","PREENCHIMENTO OBRIGATÓRIO","")
D11: Cliente | E11: Claro
D12: Tipo de Site | E12: Collo - BTS | F12: =IF(E12="","PREENCHIMENTO OBRIGATÓRIO","")

Sheet Quantitativos
B4: Quantitativos - PV
B7: Fornecedor: | C7: LS OFFICE
B8: ID Highline: | C8: PV MÉDIO CONSOLIDADO
B9: Estado | C9: TODOS
B11: Atividade | C11: Item | D11: Descrição | E11: Unid. Medida | F11: Quant | G11: Valor Unit | H11: Valor Total
B12: Serviços de Engenharia | C12: SEN01 | D12: Projeto Executivo | E12: Vb | H12: =G12*F12
B13: Serviços de Engenharia | C13: SEN02 | D13: As Built | E13: Vb | G13: 940 | H13: =G13*F13
B14: Serviços de Engenharia | C14: SEN03 | D14: Revisão de Projeto de Prefeitura (Compartilhamento ou ampliação) | E14: Vb | H14: =G14*F14
B15: Serviços de Engenharia | C15: SEN04 | D15: Revisão de Projeto Executivo (Compartilhamento ou ampliação) | E15: Vb | H15: =G15*F15
B16: Serviços de Engenharia | C16: SEN05 | D16: Revisão de As Built (Compartilhamento ou ampliação) | E16: Vb | G16: 850 | H16: =G16*F16
B17: Serviços de Engenharia | C17: SEN06 | D17: Sondagem à percussão | E17: Vb | H17: =G17*F17
B18: Serviços de Engenharia | C18: SEN07 | D18: Sondagem Rotativa | E18: Vb | H18: =G18*F18
B19: Serviços de Engenharia | C19: SEN08 | D19: Laudo Estrutural para Roof Top | E19: Vb | H19: =G19*F19
B20: Serviços de Engenharia | C20: SEN09 | D20: Projeto de Prefeitura | E20: Vb | H20: =G20*F20
B21: Serviços de Engenharia | C21: SEN10 | D21: Planialtimétrico | E21: Vb | H21: =G21*F21
B22: Serviços de Engenharia | C22: SEN11 | D22: Laudo Estrutural (RT) - Sem Vistoria | E22: Vb | H22: =G22*F22
B23: Serviços de Engenharia | C23: SEN12 | D23: Laudo Estrutural (RT) - Com Vistoria | E23: Vb | H23: =G23*F23
B24: Fundação / Comum | C24: FUNC01 | D24: Escavação Radier | E24: m³ | G24: 177.66 | H24: =G24*F24
B25: Fundação / Comum | C25: FUNC02 | D25: Escavação Tubulão | E25: m³ | H25: =G25*F25
B26: Fundação / Comum | C26: FUNC03 | D26: Concreto preparado e lançado(fck. conf.projeto) - Até 20m³ | E26: m³ | G26: 1293.22 | H26: =G26*F26
B27: Fundação / Comum | C27: FUNC04 | D27: Concreto preparado e lançado(fck. conf.projeto) - 20m³ a 50m³ | E27: m³ | H27: =G27*F27
B28: Fundação / Comum | C28: FUNC05 | D28: Concreto preparado e lançado(fck. conf.projeto) - 50m³ a 80m³ | E28: m³ | H28: =G28*F28
B29: Fundação / Comum | C29: FUNC06 | D29: Concreto preparado e lançado(fck. conf.projeto) - 80m³ a 100m³ | E29: m³ | H29: =G29*F29
B30: Fundação / Comum | C30: FUNC07 | D30: Concreto preparado e lançado(fck. conf.projeto) - Acima de 100m³ | E30: m³ | H30: =G30*F30
B31: Fundação / Comum | C31: FUNC08 | D31: Reaterro e compactação | E31: m³ | G31: 121.88 | H31: =G31*F31
B32: Fundação / Comum | C32: FUNC09 | D32: Bota-fora | E32: m³ | G32: 121.12 | H32: =G32*F32
B33: Fundação / Comum | C33: FUNC10 | D33: Forma em tábua de madeira comum | E33: m² | G33: 144.05 | H33: =G33*F33
B34: Fundação / Comum | C34: FUNC11 | D34: Aço de fundação (CA 50 / CA 60) para tubulão ou radier | E34: Kg | G34: 22.54 | H34: =G34*F34
B35: Fundação / Comum | C35: FUNC12 | D35: Lastro de brita nº 2 | E35: m³ | G35: 300 | H35: =G35*F35
B36: Fundação / Comum | C36: FUNC13 | D36: Concreto magro p/regularização (não estrutural) | E36: m³ | G36: 641.77 | H36: =G36*F36
B37: Fundação / Comum | C37: FUNC14 | D37: Concreto ciclópico | E37: m³ | H37: =G37*F37
B38: Fundação / Comum | C38: FUNC15 | D38: Limpeza e Bota Fora da Estaca Raiz | E38: Vb | H38: =G38*F38
B39: Fundação / Comum | C39: FUNC16 | D39: Encamisamento de Tubulão com manilha de concreto, incluso içamento com munck se necessário | E39: m | H39: =G39*F39
B40: Fundação / Estaca Raiz | C40: FRZ01 | D40: Mobilização perfuratriz - estaca raiz | E40: un | H40: =G40*F40
B41: Fundação / Estaca Raiz | C41: FRZ02 | D41: Perfuração + argamassa para estaca raiz (Solo Comum) | E41: m | H41: =G41*F41
B42: Fundação / Estaca Raiz | C42: FRZ03 | D42: Perfuração + argamassa para estaca raiz (Rochoso) | E42: m | H42: =G42*F42
B43: Fundação / Estaca Raiz | C43: FRZ04 | D43: Arame Recozido | E43: kg | H43: =G43*F43
B44: Fundação / Estaca Raiz | C44: FRZ05 | D44: Gerador de Energia | E44: Vb | H44: =G44*F44
B45: Fundação / Estaca Raiz | C45: FRZ06 | D45: Água para estaca-raiz (modalidade fornecimento material) | E45: m³ | H45: =G45*F45
B46: Fundação / Estaca Raiz | C46: FRZ07 | D46: Aço de fundação (CA 50 / CA 60) para estacas-raiz, blocos de coroamento e viga de ligação | E46: Kg | H46: =G46*F46
...

Sheet Resumo PV
A1: SITE ID HIGHLINE | B1: PV MÉDIO CONSOLIDADO
A2: UF | B2: TODOS
A3: REGIÃO | B3: CONSOLIDADO
A6: Item | B6: R$
A7: Serviços de Engenharia | B7: =SUM(Quantitativos!H12:H23)
A8: Fundação | B8: =SUM(Quantitativos!H24:H47)
A9: Fechamento | B9: =SUM(Quantitativos!H48:H59)
A10: Área Construída | B10: =SUM(Quantitativos!H60:H71)
A11: Energia | B11: =SUM(Quantitativos!H72:H103)
A12: Extensão de Rede | B12: =SUM(Quantitativos!H126:H161)
A13: Acesso | B13: =SUM(Quantitativos!H162:H163)
A14: Itens complementares | B14: =SUM(Quantitativos!H104:H120)
A15: Transporte | B15: =SUM(Quantitativos!H185:H189)
A16: Montagem | B16: =SUM(Quantitativos!H164:H183)
A17: Acessórios EV | B17: =SUM(Quantitativos!H116:H125)
A18: Roof Top | B18: =SUM(Quantitativos!H252:H277)
A19: Reforço | B19: =SUM(Quantitativos!H190:H277)
A20: TOTAL R$ | B20: =SUM(B7:B18)

Sheet check
G1: Região | I1: Atividades:
G2: Sul | I2: BTS
B3: Concreto | C3: =COUNTA(Quantitativos!$F$24:$F$28)<=1 | G3: Sudeste | I3: Roof Top
B4: Escavação | C4: =COUNTA(Quantitativos!$F$31:$F$32)<=1 | G4: Norte | I4: Collo - BTS
B5: Bota fora | C5: =IF(Quantitativos!F33<>(SUM(Quantitativos!F31:F32)),FALSE,TRUE) | G5: Nordeste | I5: Collo RT
G6: Centro-Oeste | I6: Reforço
I11: Algar
B12: Andre Mosquetti | I12: Claro
B13: Gleyce Caldeira | I13: Nextel
B14: Katharine Quinta | I14: Oi
B15: Vinicius Barbieri | I15: Tim
B16: Gesiel Melo | I16: Veloso
B17: Keisson Araujo | I17: Vivo
I18: WND

Sheet Análise das Médias
A1: Atividade | B1: Item | C1: Descrição | D1: Unid. | E1: Nº de PVs | F1: Média (R$) | G1: Mediana (R$) | H1: Mínimo (R$) | I1: Máximo (R$) | J1: Desvio (R$) | K1: Variação Máx/Mín
A2: Serviços de Engenharia | B2: SEN02 | C2: As Built | D2: Vb | E2: 5 | F2: 940 | G2: 900 | H2: 900 | I2: 1100 | J2: 80 | K2: 1.22
A3: Serviços de Engenharia | B3: SEN05 | C3: Revisão de As Built (Compartilhamento ou ampliação) | D3: Vb | E3: 1 | F3: 850 | G3: 850 | H3: 850 | I3: 850 | J3: 0 | K3: 1
A4: Fundação / Comum | B4: FUNC01 | C4: Escavação Radier | D4: m³ | E4: 2 | F4: 177.66 | G4: 177.66 | H4: 177.66 | I4: 177.66 | J4: 0 | K4: 1
A5: Fundação / Comum | B5: FUNC03 | C5: Concreto preparado e lançado(fck. conf.projeto) - Até 20m³ | D5: m³ | E5: 2 | F5: 1293.22 | G5: 1293.22 | H5: 1256 | I5: 1330.45 | J5: 37.23 | K5: 1.06
A6: Fundação / Comum | B6: FUNC08 | C6: Reaterro e compactação | D6: m³ | E6: 2 | F6: 121.88 | G6: 121.88 | H6: 121.88 | I6: 121.88 | J6: 0 | K6: 1
A7: Fundação / Comum | B7: FUNC09 | C7: Bota-fora | D7: m³ | E7: 4 | F7: 121.12 | G7: 120.98 | H7: 120.97 | I7: 121.54 | J7: 0.24 | K7: 1
A8: Fundação / Comum | B8: FUNC10 | C8: Forma em tábua de madeira comum | D8: m² | E8: 2 | F8: 144.05 | G8: 144.05 | H8: 144.05 | I8: 144.05 | J8: 0 | K8: 1
A9: Fundação / Comum | B9: FUNC11 | C9: Aço de fundação (CA 50 / CA 60) para tubulão ou radier | D9: Kg | E9: 2 | F9: 22.54 | G9: 22.54 | H9: 21.56 | I9: 23.52 | J9: 0.98 | K9: 1.09
A10: Fundação / Comum | B10: FUNC12 | C10: Lastro de brita nº 2 | D10: m³ | E10: 1 | F10: 300 | G10: 300 | H10: 300 | I10: 300 | J10: 0 | K10: 1
A11: Fundação / Comum | B11: FUNC13 | C11: Concreto magro p/regularização (não estrutural) | D11: m³ | E11: 2 | F11: 641.77 | G11: 641.77 | H11: 641.77 | I11: 641.77 | J11: 0 | K11: 1
A12: Fechamento | B12: FEC02 | C12: Fechamento - Alambrado c/ Arame farpado | D12: m² | E12: 24 | F12: 410.31 | G12: 367 | H12: 310 | I12: 650.23 | J12: 86.95 | K12: 2.1
A13: Fechamento | B13: FEC05 | C13: Instalação de concertina sobre alambrado (Quando solicitado pela HL) | D13: m | E13: 1 | F13: 136 | G13: 136 | H13: 136 | I13: 136 | J13: 0 | K13: 1
... A63: Roof Top | B63: RFT25 | C63: Malha de aterramento Roof Top | D63: m | E63: 1 | F63: 190 | G63: 190 | H63: 190 | I63: 190 | J63: 0 | K63: 1

Sheet PVs Considerados
A1: # | B1: Arquivo de PV | C1: Pasta
A2: 1 | B2: PV - MANAUS - AM4MNS018_AMMNSZ2_VIVO - COLLO_22032026.xlsm | C2: AM/MANAUS/AM4MNS018_AMMNSZ2_VIVO
A3: 2 | B3: PV - AMMNS010 (Highline) - AMCRG (VIVO) - COLLO_23122025.xlsm | C3: AM/MANAUS/AMMNS010 (Highline) - AMCRG (VIVO)
A4: 3 | B4: PV - BABON66 - COLLO-RT.xlsm | C4: BA/BABON66/1. Proposta_Orçamento
A5: 4 | B5: PV - CEP-MUE-008 (Highline) - CEMUE14 (CLARO)_REV00.xlsm | C5: CE/CEMUE14
A6: 5 | B6: PV - CEP-GBA-002 (Highline) - CEGBA03 (CLARO)_REV01.xlsm | C6: CE/CEP-GBA-002 (Highline) - CEGBA03 (CLARO)/1. Proposta_Orçamento
A7: 6 | B7: PV_CEARÁ_TIM_COLLO - CEP-MUE-008 (Highline) - SR-MUMUJ1 (TIM)_08072026.xlsx | C7: CE/CEP-MUE-008 (Highline) - SR-MUMUJ1 (TIM)
A8: 7 | B8: PV - DFBRS216 (HIGHLINE) - DFNAD (VIVO).xlsm | C8: DF/CEILÂNDIA
A9: 8 | B9: PV - AMARANTE DO MARANHÃO - MAMRN003 (Highline) - MAATH08 (CLARO) - COLLO_01062026.xlsm | C9: MA/AMARANTE DO MARANHÃO
A10: 9 | B10: PV - BACABAL - MABCB001_MABBL16_CLARO - COLLO_22032026.xlsm | C10: MA/BACABAL/MABCB001_MABBL16
A11: 10 | B11: PV - MAVTX006 (HIGHLINE) - MAVMS (VIVO).xlsm | C11: MA/VITÓRIA DO MEARIM
A12: 11 | B12: PV_ALTAMIRA_VIVO_COLLO - PA4-ALA-001_PASSE_10042025_REV00.xlsm | C12: PA/ALTAMIRA
A13: 12 | B13: PV_BELÉM_VIVO_COLLO - PAICO2234_PAARP_10042025_REV00.xlsm | C13: PA/BELÉM/PAICO2234 - PAARP (VIVO)/1. Proposta Orçamento
... A37: 36 | B37: PV - SPP-SPO-216 (HIGHLINE) - SPLJD (VIVO) - COLLO_21072026.xlsm | C37: SP/SPP-SPO-216 (HL) - SPLJ (VIVO)/1. Proposta Orçamento
