Workbook

Sheet Layout
D7: Data | E7: =TODAY() -> 46244 | F7: =IF(E7="","PREENCHIMENTO OBRIGATÓRIO","")
D8: ID Highline | E8: PESTA3002 | F8: =IF(E8="","PREENCHIMENTO OBRIGATÓRIO","")
D9: Região | E9: Nordeste | F9: =IF(E9="","PREENCHIMENTO OBRIGATÓRIO","")
D10: PM / Coordenador | E10: Vinicius Barbieri | F10: =IF(E10="","PREENCHIMENTO OBRIGATÓRIO","")
D11: Cliente | E11: TIM
D12: Tipo de Site | E12: Rooftop | F12: =IF(E12="","PREENCHIMENTO OBRIGATÓRIO","")

Sheet Quantitativos
B4: Quantitativos - PV
B7: Fornecedor: | C7: LS OFFICE
B8: ID Highline: | C8: =(Layout!E8) -> PESTA3002
B9: Estado | C9: PA
B11: Atividade | C11: Item | D11: Descrição | E11: Unid. Medida | F11: Quant | G11: Valor Unit | H11: Valor Total
B12: Serviços de Engenharia | C12: SEN01 | D12: Projeto Executivo | E12: Vb | G12: 0 | H12: =G12*F12 -> 0
B13: Serviços de Engenharia | C13: SEN02 | D13: As Built | E13: Vb | G13: 900 | H13: =G13*F13 -> 0
B14: Serviços de Engenharia | C14: SEN03 | D14: Revisão de Projeto de Prefeitura (Compartilhamento ou ampliação) | E14: Vb | G14: 0 | H14: =G14*F14 -> 0
B15: Serviços de Engenharia | C15: SEN04 | D15: Revisão de Projeto Executivo (Compartilhamento ou ampliação) | E15: Vb | G15: 0 | H15: =G15*F15 -> 0
B16: Serviços de Engenharia | C16: SEN05 | D16: Revisão de As Built (Compartilhamento ou ampliação) | E16: Vb | G16: 0 | H16: =G16*F16 -> 0
B17: Serviços de Engenharia | C17: SEN06 | D17: Sondagem à percussão | E17: Vb | G17: 0 | H17: =G17*F17 -> 0
B18: Serviços de Engenharia | C18: SEN07 | D18: Sondagem Rotativa | E18: Vb | G18: 0 | H18: =G18*F18 -> 0
B19: Serviços de Engenharia | C19: SEN08 | D19: Laudo Estrutural para Roof Top | E19: Vb | G19: 0 | H19: =G19*F19 -> 0
B20: Serviços de Engenharia | C20: SEN09 | D20: Projeto de Prefeitura | E20: Vb | G20: 0 | H20: =G20*F20 -> 0
B21: Serviços de Engenharia | C21: SEN10 | D21: Planialtimétrico | E21: Vb | G21: 0 | H21: =G21*F21 -> 0
B22: Serviços de Engenharia | C22: SEN11 | D22: Laudo Estrutural (RT) - Sem Vistoria | E22: Vb | G22: 0 | H22: =G22*F22 -> 0
B23: Serviços de Engenharia | C23: SEN12 | D23: Laudo Estrutural (RT) - Com Vistoria | E23: Vb | G23: 0 | H23: =G23*F23 -> 0
... B64: Área Construída | C64: CON06 | D64: Base de equipamento em concreto armado | E64: m³ | G64: 3645.25 | H64: =G64*F64 -> 0
B65: Área Construída | C65: CON07 | D65: Skid metálico (galvanizado à fogo) | E65: Kg | F65: 120 | G65: 55 | H65: =G65*F65 -> 6600
B66: Área Construída | C66: CON08 | D66: Adequação/Alvenaria - Em muro existente | E66: m² | G66: 0 | H66: =G66*F66 -> 0
B67: Área Construída | C67: CON09 | D67: Chapisco de muro - Em muro existente | E67: m² | G67: 0 | H67: =G67*F67 -> 0
B68: Área Construída | C68: CON10 | D68: Demolição de muro existente | E68: m² | G68: 0 | H68: =G68*F68 -> 0
B69: Área Construída | C69: CON11 | D69: Muro de arrimo | E69: m² | G69: 0 | H69: =G69*F69 -> 0
B70: Área Construída | C70: CON12 | D70: Execução de Muro em Alvenaria | E70: m² | G70: 0 | H70: =G70*F70 -> 0
B71: Área Construída | C71: CON13 | D71: Conector FCI Barra - Para esteira | E71: un | G71: 178.2 | H71: =G71*F71 -> 0
B72: Energia / Entrada de Energia | C72: ENT01 | D72: QD/ QTM - Com Alvenaria (Padrão Claro) | E72: un | G72: 12994.74 | H72: =G72*F72 -> 0
B73: Energia / Entrada de Energia | C73: ENT02 | D73: QD/ QTM - Com Alvenaria (Padrão Vivo) | E73: un | G73: 13994.74 | H73: =G73*F73 -> 0
B74: Energia / Entrada de Energia | C74: ENT03 | D74: QD/ QTM - Com Alvenaria (Padrão Tim) | E74: un | F74: 1 | G74: 13990 | H74: =G74*F74 -> 13990
B75: Energia / Entrada de Energia | C75: ENT02 | D75: Suporte para QD/ QTM | E75: un
B76: Energia / Entrada de Energia | C76: ENT03 | D76: Grade para medidor | E76: un | G76: 1350 | H76: =G76*F76 -> 0
B77: Energia / Entrada de Energia | C77: ENT04 | D77: Tomada Steck | E77: un | G77: 350 | H77: =G77*F77 -> 0
B78: Energia / Entrada de Energia | C78: ENT05 | D78: Padrão novo para 1 medidor - Com ligação definitiva | E78: un | G78: 0 | H78: =G78*F78 -> 0
B79: Energia / Entrada de Energia | C79: ENT06 | D79: Padrão novo para 2 medidores - Com ligação definitiva | E79: un | G79: 0 | H79: =G79*F79 -> 0
B80: Energia / Entrada de Energia | C80: ENT07 | D80: Ampliação do padrão de 1 para 2 medidores - Com ligação definitiva | E80: un | F80: 1 | G80: 8450 | H80: =G80*F80 -> 8450
B81: Energia / Entrada de Energia | C81: ENT08 | D81: Ampliação do padrão de 2 para 3 medidores - Com ligação definitiva | E81: un | G81: 0 | H81: =G81*F81 -> 0
B82: Energia / Entrada de Energia | C82: ENT09 | D82: Ampliação do padrão de 3 para 4 medidores - Com ligação definitiva | E82: un | G82: 0 | H82: =G82*F82 -> 0
B83: Energia / Entrada de Energia | C83: ENT10 | D83: Ampliação do padrão de 4 para 5 medidores - Com ligação definitiva | E83: un | G83: 0 | H83: =G83*F83 -> 0
B84: Energia / Entrada de Energia | C84: ENT11 | D84: Projeto de ampliação do padrão - Memorial, carta de aprovação e ART | E84: un | G84: 0 | H84: =G84*F84 -> 0
B85: Energia / Entrada de Energia | C85: ENT12 | D85: Cabo Cobre Isolado EPR-06/1KV # 4mm² | E85: m | G85: 0 | H85: =G85*F85 -> 0
B86: Energia / Entrada de Energia | C86: ENT13 | D86: Eletroduto Corrugado Tipo KANAFLEX Ø 1" | E86: m | G86: 25 | H86: =G86*F86 -> 0
...

Sheet Resumo PV
A1: SITE ID HIGHLINE | B1: =Quantitativos!C8 -> PESTA3002
A2: UF | B2: =(Quantitativos!C9) -> PA
A3: REGIÃO | B3: =Layout!E9 -> Nordeste
A6: Item | B6: R$
A7: Serviços de Engenharia | B7: =SUM(Quantitativos!H12:H23) -> 0
A8: Fundação | B8: =SUM(Quantitativos!H24:H47) -> 0
A9: Fechamento | B9: =SUM(Quantitativos!H48:H59) -> 0
A10: Área Construída | B10: =SUM(Quantitativos!H60:H71) -> 6600
A11: Energia | B11: =SUM(Quantitativos!H72:H98) -> 29495
A12: Extensão de Rede | B12: =SUM(Quantitativos!H121:H156) -> 0
A13: Acesso | B13: =SUM(Quantitativos!H157:H158) -> 0
A14: Itens complementares | B14: =SUM(Quantitativos!H99:H115) -> 0
A15: Transporte | B15: =SUM(Quantitativos!H180:H184) -> 0
A16: Montagem | B16: =SUM(Quantitativos!H159:H178) -> 0
A17: Acessórios EV | B17: =SUM(Quantitativos!H111:H120) -> 2700
A18: Roof Top | B18: =SUM(Quantitativos!H247:H272) -> 13870
A19: Reforço | B19: =SUM(Quantitativos!H185:H272) -> 13870
A20: TOTAL R$ | B20: =SUM(B7:B18) -> 52665

Sheet check
G1: Região | I1: Atividades:
G2: Sul | I2: BTS
B3: Concreto | C3: =COUNTA(Quantitativos!$F$24:$F$28)<=1 -> TRUE | G3: Sudeste | I3: Roof Top
B4: Escavação | C4: =COUNTA(Quantitativos!$F$31:$F$32)<=1 -> TRUE | G4: Norte | I4: Collo - BTS
B5: Bota fora | C5: =IF(Quantitativos!F33<>(SUM(Quantitativos!F31:F32)),FALSE(),TRUE()) -> TRUE | G5: Nordeste | I5: Collo RT
G6: Centro-Oeste | I6: Reforço
I11: Algar
B12: Andre Mosquetti | I12: Claro
B13: Gleyce Caldeira | I13: Nextel
B14: Katharine Quinta | I14: Oi
B15: Vinicius Barbieri | I15: Tim
B16: Gesiel Melo | I16: Veloso
B17: Keisson Araujo | I17: Vivo
I18: WND
